Workbook

Sheet SAQIB
A1: CURATECH PHARMA (PVT) LTD
A3: SUMMARY OF (MIO) TARGET JULY-2025
A5: MUHAMMAD SAQIB (MIO)
A6: SR.NO | B6: PRODUCT NAME | C6: PACK SIZE | D6: RATE | E6: MONTHLY PER HEAD TGT | F6: 1 TO 7 | J6: 8 TO 14 | O6: 15 T0 21 | S6: 22 TO 28 | W6: TOTAL
F7: TGT UNITS | H7: ACHI | I7: % | J7: TGT UNITS | L7: ACHI | N7: % | O7: TGT UNITS | Q7: ACHI | R7: % | S7: TGT UNITS | U7: ACHI | V7: % | W7: TGT UNITS | Y7: ACHI | AA7: %
A8: 1 | B8: Curaxone 250mg IM | C8: 1 Vial | D8: 70.79 | E8: 500 | F8: =W8/2 -> 646 | G8: =F8*D8 -> 45730.34 | J8: 646 | K8: =J8*D8 -> 45730.34 | L8: 0 | M8: =L8*D8 -> 0 | N8: =L8/J8 -> 0 | O8: =W8/2 -> 646 | P8: =O8*D8 -> 45730.34 | S8: 646 | T8: =S8*D8 -> 45730.34 | W8: 1292 | X8: =W8*D8 -> 91460.68 | Y8: 0 | Z8: =Y8*D8 -> 0 | AA8: =Y8/W8 -> 0
A9: 2 | B9: Curaxone 500mg IV | C9: 1 Vial | D9: 89.37 | E9: 500 | F9: =W9/2 -> 646 | G9: =F9*D9 -> 57733.02 | J9: 646 | K9: =J9*D9 -> 57733.02 | L9: 55 | M9: =L9*D9 -> 4915.35 | N9: =L9/J9 -> 0.085139319 | O9: =W9/2 -> 646 | P9: =O9*D9 -> 57733.02 | S9: 646 | T9: =S9*D9 -> 57733.02 | W9: 1292 | X9: =W9*D9 -> 115466.04 | Y9: 0 | Z9: =Y9*D9 -> 0 | AA9: =Y9/W9 -> 0
A10: 3 | B10: Curaxone IG IV | C10: 1 Vial | D10: 112.5 | E10: 800 | F10: =W10/2 -> 1033.5 | G10: =F10*D10 -> 116268.75 | J10: 1033.5 | K10: =J10*D10 -> 116268.75 | L10: 931 | M10: =L10*D10 -> 104737.5 | N10: =L10/J10 -> 0.90082245 | O10: =W10/2 -> 1033.5 | P10: =O10*D10 -> 116268.75 | S10: 1033.5 | T10: =S10*D10 -> 116268.75 | W10: 2067 | X10: =W10*D10 -> 232537.5 | Y10: 2000 | Z10: =Y10*D10 -> 225000 | AA10: =Y10/W10 -> 0.96758587
A11: 4 | B11: Mecoline 500mcg 20's | C11: 20's | D11: 55.23 | E11: 200 | F11: =W11/2 -> 258.5 | G11: =F11*D11 -> 14276.955 | J11: 258.5 | K11: =J11*D11 -> 14276.955 | L11: 0 | M11: =L11*D11 -> 0 | N11: =L11/J11 -> 0 | O11: =W11/2 -> 258.5 | P11: =O11*D11 -> 14276.955 | S11: 258.5 | T11: =S11*D11 -> 14276.955 | W11: 517 | X11: =W11*D11 -> 28553.91 | Y11: 20 | Z11: =Y11*D11 -> 1104.6 | AA11: =Y11/W11 -> 0.03868472
A12: 5 | B12: Mecoline 500mcg 100's | C12: 100's | D12: 192.63 | E12: 192 | F12: =W12/2 -> 248 | G12: =F12*D12 -> 47772.24 | J12: 248 | K12: =J12*D12 -> 47772.24 | L12: 2 | M12: =L12*D12 -> 385.26 | N12: =L12/J12 -> 0.0080645161 | O12: =W12/2 -> 248 | P12: =O12*D12 -> 47772.24 | S12: 248 | T12: =S12*D12 -> 47772.24 | W12: 496 | X12: =W12*D12 -> 95544.48 | Y12: 28 | Z12: =Y12*D12 -> 5393.64 | AA12: =Y12/W12 -> 0.056451613
A13: 6 | B13: SUDROPROXIM TAB | C13: 100's | D13: 195 | E13: 30 | F13: =W13/2 -> 39 | G13: =F13*D13 -> 7605 | J13: 39 | K13: =J13*D13 -> 7605 | L13: 0 | M13: =L13*D13 -> 0 | N13: =L13/J13 -> 0 | O13: =W13/2 -> 39 | P13: =O13*D13 -> 7605 | S13: 39 | T13: =S13*D13 -> 7605 | W13: 78 | X13: =W13*D13 -> 15210 | Y13: 0 | Z13: =Y13*D13 -> 0 | AA13: =Y13/W13 -> 0
A14: 7 | B14: SUDROPROXIM FORTE TAB | C14: 100's | D14: 648.52 | E14: 30 | F14: =W14/2 -> 39 | G14: =F14*D14 -> 25292.28 | J14: 39 | K14: =J14*D14 -> 25292.28 | L14: 0 | M14: =L14*D14 -> 0 | N14: =L14/J14 -> 0 | O14: =W14/2 -> 39 | P14: =O14*D14 -> 25292.28 | S14: 39 | T14: =S14*D14 -> 25292.28 | W14: 78 | X14: =W14*D14 -> 50584.56 | Y14: 4 | Z14: =Y14*D14 -> 2594.08 | AA14: =Y14/W14 -> 0.051282051
A15: 8 | B15: TECHFEN P Tab 50mg | C15: 20's | D15: 51 | E15: 300 | F15: =W15/2 -> 387.5 | G15: =F15*D15 -> 19762.5 | J15: 387.5 | K15: =J15*D15 -> 19762.5 | L15: 52 | M15: =L15*D15 -> 2652 | N15: =L15/J15 -> 0.13419355 | O15: =W15/2 -> 387.5 | P15: =O15*D15 -> 19762.5 | S15: 387.5 | T15: =S15*D15 -> 19762.5 | W15: 775 | X15: =W15*D15 -> 39525 | Y15: 148 | Z15: =Y15*D15 -> 7548 | AA15: =Y15/W15 -> 0.19096774
A16: 9 | B16: Zicure 250mg Cap 10's | C16: 10's | D16: 189.25 | E16: 560 | F16: =W16/2 -> 723.5 | G16: =F16*D16 -> 136922.38 | J16: 723.5 | K16: =J16*D16 -> 136922.38 | L16: 20 | M16: =L16*D16 -> 3785 | N16: =L16/J16 -> 0.0276434 | O16: =W16/2 -> 723.5 | P16: =O16*D16 -> 136922.38 | S16: 723.5 | T16: =S16*D16 -> 136922.38 | W16: 1447 | X16: =W16*D16 -> 273844.75 | Y16: 77 | Z16: =Y16*D16 -> 14572.25 | AA16: =Y16/W16 -> 0.053213545
A17: 10 | B17: Zicure 250mg Cap 6's | C17: 6's | D17: 128.86 | E17: 550 | F17: =W17/2 -> 710.5 | G17: =F17*D17 -> 91555.03 | J17: 710.5 | K17: =J17*D17 -> 91555.03 | L17: 3 | M17: =L17*D17 -> 386.58 | N17: =L17/J17 -> 0.0042223786 | O17: =W17/2 -> 710.5 | P17: =O17*D17 -> 91555.03 | S17: 710.5 | T17: =S17*D17 -> 91555.03 | W17: 1421 | X17: =W17*D17 -> 183110.06 | Y17: 0 | Z17: =Y17*D17 -> 0 | AA17: =Y17/W17 -> 0
A18: 11 | B18: Curatral 100mg Cap | C18: 4's | D18: 94.9 | E18: 650 | F18: =W18/2 -> 839.5 | G18: =F18*D18 -> 79668.55 | J18: 839.5 | K18: =J18*D18 -> 79668.55 | L18: 40 | M18: =L18*D18 -> 3796 | N18: =L18/J18 -> 0.047647409 | O18: =W18/2 -> 839.5 | P18: =O18*D18 -> 79668.55 | S18: 839.5 | T18: =S18*D18 -> 79668.55 | W18: 1679 | X18: =W18*D18 -> 159337.1 | Y18: 86 | Z18: =Y18*D18 -> 8161.4 | AA18: =Y18/W18 -> 0.051220965
A19: 12 | B19: TECHFEN SR Tab 100mg | C19: 30's | D19: 85.33 | E19: 550 | F19: =W19/2 -> 710.5 | G19: =F19*D19 -> 60626.965 | J19: 710.5 | K19: =J19*D19 -> 60626.965 | L19: 159 | M19: =L19*D19 -> 13567.47 | N19: =L19/J19 -> 0.22378607 | O19: =W19/2 -> 710.5 | P19: =O19*D19 -> 60626.965 | S19: 710.5 | T19: =S19*D19 -> 60626.965 | W19: 1421 | X19: =W19*D19 -> 121253.93 | Y19: 268 | Z19: =Y19*D19 -> 22868.44 | AA19: =Y19/W19 -> 0.18859958
... A22: 15 | B22: Pirotech 20mg Tab | C22: 20's | D22: 89.64 | E22: 300 | F22: =W22/2 -> 387.5 | G22: =F22*D22 -> 34735.5 | J22: 387.5 | K22: =J22*D22 -> 34735.5 | L22: 77 | M22: =L22*D22 -> 6902.28 | N22: =L22/J22 -> 0.19870968 | O22: =W22/2 -> 387.5 | P22: =O22*D22 -> 34735.5 | S22: 387.5 | T22: =S22*D22 -> 34735.5 | W22: 775 | X22: =W22*D22 -> 69471 | Y22: 47 | Z22: =Y22*D22 -> 4213.08 | AA22: =Y22/W22 -> 0.060645161
A23: Total Life Line Group Units | F23: =SUM(F8:F22) -> 7121.5 | G23: =F23*D23 -> 0 | J23: =SUM(J8:J22) -> 7121.5 | K23: =SUM(K8:K22) -> 773943.19 | L23: =SUM(L8:L22) -> 1339 | M23: =SUM(M8:M22) -> 141127.44 | N23: =L23/J23 -> 0.18802219 | O23: =SUM(O8:O22) -> 7121.5 | P23: =O23*D23 -> 0 | S23: =SUM(S8:S22) -> 7121.5 | T23: =SUM(T8:T22) -> 773943.19 | W23: =SUM(W8:W22) -> 14243 | X23: =W23*D23 -> 0 | Y23: 3659 | Z23: =Z22+Z21+Z20+Z19+Z18+Z17+Z16+Z15+Z14+Z13+Z12+Z11+Z10+Z9+Z8 -> 291455.49 | AA23: =Y23/W23 -> 0.25689813
A24: Total Life Line Group Value | E24: =SUM(E8:E23) -> 5512 | F24: =G24 -> 773943.19 | G24: =SUM(G8:G23) -> 773943.19 | J24: =K23 -> 773943.19 | L24: =M23 -> 141127.44 | N24: =L24/J24 -> 0.18234858 | O24: =P24 -> 773943.19 | P24: =SUM(P8:P23) -> 773943.19 | S24: =T23 -> 773943.19 | W24: =X24 -> 1547886.4 | X24: =SUM(X8:X23) -> 1547886.4 | Y24: =Z23 -> 291455.49 | AA24: =Y24/W24 -> 0.18829256
B27: Signature:

Sheet ZEESHAN
A1: CURATECH PHARMA (PVT) LTD
A3: SUMMARY OF (MIO) TARGET JULY-2025
A5: ZEESHAN (MIO)
A6: SR.NO | B6: PRODUCT NAME | C6: PACK SIZE | D6: RATE | E6: MONTHLY PER HEAD TGT | F6: 1 TO 7 | J6: 8 TO 14 | O6: 15 T0 21 | S6: 22 TO 28 | W6: TOTAL
F7: TGT UNITS | H7: ACHI | I7: % | J7: TGT UNITS | L7: ACHI | N7: % | O7: TGT UNITS | Q7: ACHI | R7: % | S7: TGT UNITS | U7: ACHI | V7: % | W7: TGT UNITS | Y7: ACHI | AA7: %
A8: 1 | B8: Curaxone 250mg IM | C8: 1 Vial | D8: 70.79 | E8: 500 | F8: =W8/2 -> 646 | G8: =F8*D8 -> 45730.34 | J8: 646 | K8: =J8*D8 -> 45730.34 | L8: 0 | M8: =L8*D8 -> 0 | N8: =L8/J8 -> 0 | O8: =W8/2 -> 646 | P8: =O8*D8 -> 45730.34 | S8: 646 | T8: =S8*D8 -> 45730.34 | W8: 1292 | X8: =W8*D8 -> 91460.68 | Y8: 10 | Z8: =Y8*D8 -> 707.9 | AA8: =Y8/W8 -> 0.0077399381
A9: 2 | B9: Curaxone 500mg IV | C9: 1 Vial | D9: 89.37 | E9: 500 | F9: =W9/2 -> 646 | G9: =F9*D9 -> 57733.02 | J9: 646 | K9: =J9*D9 -> 57733.02 | L9: 0 | M9: =L9*D9 -> 0 | N9: =L9/J9 -> 0 | O9: =W9/2 -> 646 | P9: =O9*D9 -> 57733.02 | S9: 646 | T9: =S9*D9 -> 57733.02 | W9: 1292 | X9: =W9*D9 -> 115466.04 | Y9: 32 | Z9: =Y9*D9 -> 2859.84 | AA9: =Y9/W9 -> 0.024767802
A10: 3 | B10: Curaxone IG IV | C10: 1 Vial | D10: 112.5 | E10: 800 | F10: =W10/2 -> 1033.5 | G10: =F10*D10 -> 116268.75 | J10: 1033.5 | K10: =J10*D10 -> 116268.75 | L10: 587 | M10: =L10*D10 -> 66037.5 | N10: =L10/J10 -> 0.56797291 | O10: =W10/2 -> 1033.5 | P10: =O10*D10 -> 116268.75 | S10: 1033.5 | T10: =S10*D10 -> 116268.75 | W10: 2067 | X10: =W10*D10 -> 232537.5 | Y10: 1953 | Z10: =Y10*D10 -> 219712.5 | AA10: =Y10/W10 -> 0.94484761
A11: 4 | B11: Mecoline 500mcg 20's | C11: 20's | D11: 55.23 | E11: 200 | F11: =W11/2 -> 258.5 | G11: =F11*D11 -> 14276.955 | J11: 258.5 | K11: =J11*D11 -> 14276.955 | L11: 0 | M11: =L11*D11 -> 0 | N11: =L11/J11 -> 0 | O11: =W11/2 -> 258.5 | P11: =O11*D11 -> 14276.955 | S11: 258.5 | T11: =S11*D11 -> 14276.955 | W11: 517 | X11: =W11*D11 -> 28553.91 | Y11: 0 | Z11: =Y11*D11 -> 0 | AA11: =Y11/W11 -> 0
A12: 5 | B12: Mecoline 500mcg 100's | C12: 100's | D12: 192.63 | E12: 192 | F12: =W12/2 -> 248 | G12: =F12*D12 -> 47772.24 | J12: 248 | K12: =J12*D12 -> 47772.24 | L12: 4 | M12: =L12*D12 -> 770.52 | N12: =L12/J12 -> 0.016129032 | O12: =W12/2 -> 248 | P12: =O12*D12 -> 47772.24 | S12: 248 | T12: =S12*D12 -> 47772.24 | W12: 496 | X12: =W12*D12 -> 95544.48 | Y12: 4 | Z12: =Y12*D12 -> 770.52 | AA12: =Y12/W12 -> 0.0080645161
A13: 6 | B13: SUDROPROXIM TAB | C13: 100's | D13: 195 | E13: 30 | F13: =W13/2 -> 39 | G13: =F13*D13 -> 7605 | J13: 39 | K13: =J13*D13 -> 7605 | L13: 0 | M13: =L13*D13 -> 0 | N13: =L13/J13 -> 0 | O13: =W13/2 -> 39 | P13: =O13*D13 -> 7605 | S13: 39 | T13: =S13*D13 -> 7605 | W13: 78 | X13: =W13*D13 -> 15210 | Y13: 0 | Z13: =Y13*D13 -> 0 | AA13: =Y13/W13 -> 0
A14: 7 | B14: SUDROPROXIM FORTE TAB | C14: 100's | D14: 648.52 | E14: 30 | F14: =W14/2 -> 39 | G14: =F14*D14 -> 25292.28 | J14: 39 | K14: =J14*D14 -> 25292.28 | L14: 2 | M14: =L14*D14 -> 1297.04 | N14: =L14/J14 -> 0.051282051 | O14: =W14/2 -> 39 | P14: =O14*D14 -> 25292.28 | S14: 39 | T14: =S14*D14 -> 25292.28 | W14: 78 | X14: =W14*D14 -> 50584.56 | Y14: 0 | Z14: =Y14*D14 -> 0 | AA14: =Y14/W14 -> 0
A15: 8 | B15: TECHFEN P Tab 50mg | C15: 20's | D15: 51 | E15: 300 | F15: =W15/2 -> 387.5 | G15: =F15*D15 -> 19762.5 | J15: 387.5 | K15: =J15*D15 -> 19762.5 | L15: 107 | M15: =L15*D15 -> 5457 | N15: =L15/J15 -> 0.27612903 | O15: =W15/2 -> 387.5 | P15: =O15*D15 -> 19762.5 | S15: 387.5 | T15: =S15*D15 -> 19762.5 | W15: 775 | X15: =W15*D15 -> 39525 | Y15: 39 | Z15: =Y15*D15 -> 1989 | AA15: =Y15/W15 -> 0.050322581
A16: 9 | B16: Zicure 250mg Cap 10's | C16: 10's | D16: 189.25 | E16: 560 | F16: =W16/2 -> 723.5 | G16: =F16*D16 -> 136922.38 | J16: 723.5 | K16: =J16*D16 -> 136922.38 | L16: 70 | M16: =L16*D16 -> 13247.5 | N16: =L16/J16 -> 0.0967519 | O16: =W16/2 -> 723.5 | P16: =O16*D16 -> 136922.38 | S16: 723.5 | T16: =S16*D16 -> 136922.38 | W16: 1447 | X16: =W16*D16 -> 273844.75 | Y16: 57 | Z16: =Y16*D16 -> 10787.25 | AA16: =Y16/W16 -> 0.039391845
A17: 10 | B17: Zicure 250mg Cap 6's | C17: 6's | D17: 128.86 | E17: 550 | F17: =W17/2 -> 710.5 | G17: =F17*D17 -> 91555.03 | J17: 710.5 | K17: =J17*D17 -> 91555.03 | L17: 0 | M17: =L17*D17 -> 0 | N17: =L17/J17 -> 0 | O17: =W17/2 -> 710.5 | P17: =O17*D17 -> 91555.03 | S17: 710.5 | T17: =S17*D17 -> 91555.03 | W17: 1421 | X17: =W17*D17 -> 183110.06 | Y17: 0 | Z17: =Y17*D17 -> 0 | AA17: =Y17/W17 -> 0
A18: 11 | B18: Curatral 100mg Cap | C18: 4's | D18: 94.9 | E18: 650 | F18: =W18/2 -> 839.5 | G18: =F18*D18 -> 79668.55 | J18: 839.5 | K18: =J18*D18 -> 79668.55 | L18: 62 | M18: =L18*D18 -> 5883.8 | N18: =L18/J18 -> 0.073853484 | O18: =W18/2 -> 839.5 | P18: =O18*D18 -> 79668.55 | S18: 839.5 | T18: =S18*D18 -> 79668.55 | W18: 1679 | X18: =W18*D18 -> 159337.1 | Y18: 23 | Z18: =Y18*D18 -> 2182.7 | AA18: =Y18/W18 -> 0.01369863
A19: 12 | B19: TECHFEN SR Tab 100mg | C19: 30's | D19: 85.33 | E19: 550 | F19: =W19/2 -> 710.5 | G19: =F19*D19 -> 60626.965 | J19: 710.5 | K19: =J19*D19 -> 60626.965 | L19: 153 | M19: =L19*D19 -> 13055.49 | N19: =L19/J19 -> 0.21534131 | O19: =W19/2 -> 710.5 | P19: =O19*D19 -> 60626.965 | S19: 710.5 | T19: =S19*D19 -> 60626.965 | W19: 1421 | X19: =W19*D19 -> 121253.93 | Y19: 151 | Z19: =Y19*D19 -> 12884.83 | AA19: =Y19/W19 -> 0.10626319
... A22: 15 | B22: Pirotech 20mg Tab | C22: 20's | D22: 89.64 | E22: 300 | F22: =W22/2 -> 387.5 | G22: =F22*D22 -> 34735.5 | J22: 387.5 | K22: =J22*D22 -> 34735.5 | L22: 7 | M22: =L22*D22 -> 627.48 | N22: =L22/J22 -> 0.018064516 | O22: =W22/2 -> 387.5 | P22: =O22*D22 -> 34735.5 | S22: 387.5 | T22: =S22*D22 -> 34735.5 | W22: 775 | X22: =W22*D22 -> 69471 | Y22: 7 | Z22: =Y22*D22 -> 627.48 | AA22: =Y22/W22 -> 0.0090322581
A23: Total Life Line Group Units | F23: =SUM(F8:F22) -> 7121.5 | G23: =F23*D23 -> 0 | J23: =SUM(J8:J22) -> 7121.5 | K23: =SUM(K8:K22) -> 773943.19 | L23: =SUM(L8:L22) -> 992 | M23: =SUM(M8:M22) -> 106376.33 | N23: =L23/J23 -> 0.1392965 | O23: =SUM(O8:O22) -> 7121.5 | P23: =O23*D23 -> 0 | S23: =SUM(S8:S22) -> 7121.5 | T23: =SUM(T8:T22) -> 773943.19 | W23: =SUM(W8:W22) -> 14243 | X23: =W23*D23 -> 0 | Y23: =SUM(Y8:Y22) -> 2276 | Z23: =Z22+Z21+Z20+Z19+Z18+Z17+Z16+Z15+Z14+Z13+Z12+Z11+Z10+Z9+Z8 -> 252522.02 | AA23: =Y23/W23 -> 0.1597978
A24: Total Life Line Group Value | E24: =SUM(E8:E23) -> 5512 | F24: =G24 -> 773943.19 | G24: =SUM(G8:G23) -> 773943.19 | J24: =K23 -> 773943.19 | L24: =M23 -> 106376.33 | N24: =L24/J24 -> 0.13744721 | O24: =P24 -> 773943.19 | P24: =SUM(P8:P23) -> 773943.19 | S24: =T23 -> 773943.19 | W24: =X24 -> 1547886.4 | X24: =SUM(X8:X23) -> 1547886.4 | Y24: =Z23 -> 252522.02 | AA24: =Y24/W24 -> 0.16313989

Sheet HAMID
A1: CURATECH PHARMA (PVT) LTD
A3: SUMMARY OF (A.ASM) TARGET JULY-2025
A5: HAMID MUKHTAR (A.ASM)
A6: SR.NO | B6: PRODUCT NAME | C6: PACK SIZE | D6: RATE | E6: MONTHLY PER HEAD TGT | F6: 1 TO 7 | J6: 8 TO 14 | O6: 15 T0 21 | S6: 22 TO 28 | W6: TOTAL
F7: TGT UNITS | H7: ACHI | I7: % | J7: TGT UNITS | L7: ACHI | N7: % | O7: TGT UNITS | Q7: ACHI | R7: % | S7: TGT UNITS | U7: ACHI | V7: % | W7: TGT UNITS | Y7: ACHI | Z7: %
A8: 1 | B8: Curaxone 250mg IM | C8: 1 Vial | D8: 70.79 | E8: 500 | F8: =W8/26*7 -> 695.69231 | G8: =F8*D8 -> 49248.058 | J8: 695.69231 | K8: =J8*D8 -> 49248.058 | L8: 0 | M8: =L8*D8 -> 0 | N8: =L8/J8 -> 0 | O8: 695.69231 | P8: =O8*D8 -> 49248.058 | S8: 695.69231 | T8: =S8*D8 -> 49248.058 | W8: =ZEESHAN!W8+SAQIB!W8 -> 2584 | X8: =W8*D8 -> 182921.36 | Y8: =ZEESHAN!Y8+SAQIB!Y8 -> 10 | Z8: =Y8/W8 -> 0.003869969
A9: 2 | B9: Curaxone 500mg IV | C9: 1 Vial | D9: 89.37 | E9: 500 | F9: =W9/26*7 -> 695.69231 | G9: =F9*D9 -> 62174.022 | J9: 695.69231 | K9: =J9*D9 -> 62174.022 | L9: 55 | M9: =L9*D9 -> 4915.35 | N9: =L9/J9 -> 0.079057939 | O9: 695.69231 | P9: =O9*D9 -> 62174.022 | S9: 695.69231 | T9: =S9*D9 -> 62174.022 | W9: =ZEESHAN!W9+SAQIB!W9 -> 2584 | X9: =W9*D9 -> 230932.08 | Y9: =ZEESHAN!Y9+SAQIB!Y9 -> 32 | Z9: =Y9/W9 -> 0.012383901
A10: 3 | B10: Curaxone IG IV | C10: 1 Vial | D10: 112.5 | E10: 800 | F10: =W10/26*7 -> 1113 | G10: =F10*D10 -> 125212.5 | J10: 1113 | K10: =J10*D10 -> 125212.5 | L10: 1518 | M10: =L10*D10 -> 170775 | N10: =L10/J10 -> 1.3638814 | O10: 1113 | P10: =O10*D10 -> 125212.5 | S10: 1113 | T10: =S10*D10 -> 125212.5 | W10: =ZEESHAN!W10+SAQIB!W10 -> 4134 | X10: =W10*D10 -> 465075 | Y10: =ZEESHAN!Y10+SAQIB!Y10 -> 3953 | Z10: =Y10/W10 -> 0.95621674
A11: 4 | B11: Mecoline 500mcg 20's | C11: 20's | D11: 55.23 | E11: 200 | F11: =W11/26*7 -> 278.38462 | G11: =F11*D11 -> 15375.182 | J11: 278.38462 | K11: =J11*D11 -> 15375.182 | L11: 0 | M11: =L11*D11 -> 0 | N11: =L11/J11 -> 0 | O11: 278.38462 | P11: =O11*D11 -> 15375.182 | S11: 278.38462 | T11: =S11*D11 -> 15375.182 | W11: =ZEESHAN!W11+SAQIB!W11 -> 1034 | X11: =W11*D11 -> 57107.82 | Y11: =ZEESHAN!Y11+SAQIB!Y11 -> 20 | Z11: =Y11/W11 -> 0.01934236
A12: 5 | B12: Mecoline 500mcg 100's | C12: 100's | D12: 192.63 | E12: 192 | F12: =W12/26*7 -> 267.07692 | G12: =F12*D12 -> 51447.028 | J12: 267.07692 | K12: =J12*D12 -> 51447.028 | L12: 6 | M12: =L12*D12 -> 1155.78 | N12: =L12/J12 -> 0.022465438 | O12: 267.07692 | P12: =O12*D12 -> 51447.028 | S12: 267.07692 | T12: =S12*D12 -> 51447.028 | W12: =ZEESHAN!W12+SAQIB!W12 -> 992 | X12: =W12*D12 -> 191088.96 | Y12: =ZEESHAN!Y12+SAQIB!Y12 -> 32 | Z12: =Y12/W12 -> 0.032258065
A13: 6 | B13: SUDROPROXIM TAB | C13: 100's | D13: 195 | E13: 30 | F13: =W13/26*7 -> 42 | G13: =F13*D13 -> 8190 | J13: 42 | K13: =J13*D13 -> 8190 | L13: 0 | M13: =L13*D13 -> 0 | N13: =L13/J13 -> 0 | O13: 42 | P13: =O13*D13 -> 8190 | S13: 42 | T13: =S13*D13 -> 8190 | W13: =ZEESHAN!W13+SAQIB!W13 -> 156 | X13: =W13*D13 -> 30420 | Y13: =ZEESHAN!Y13+SAQIB!Y13 -> 0 | Z13: =Y13/W13 -> 0
A14: 7 | B14: SUDROPROXIM FORTE TAB | C14: 100's | D14: 648.52 | E14: 30 | F14: =W14/26*7 -> 42 | G14: =F14*D14 -> 27237.84 | J14: 42 | K14: =J14*D14 -> 27237.84 | L14: 2 | M14: =L14*D14 -> 1297.04 | N14: =L14/J14 -> 0.047619048 | O14: 42 | P14: =O14*D14 -> 27237.84 | S14: 42 | T14: =S14*D14 -> 27237.84 | W14: =ZEESHAN!W14+SAQIB!W14 -> 156 | X14: =W14*D14 -> 101169.12 | Y14: =ZEESHAN!Y14+SAQIB!Y14 -> 4 | Z14: =Y14/W14 -> 0.025641026
A15: 8 | B15: TECHFEN P Tab 50mg | C15: 20's | D15: 51 | E15: 300 | F15: =W15/26*7 -> 417.30769 | G15: =F15*D15 -> 21282.692 | J15: 417.30769 | K15: =J15*D15 -> 21282.692 | L15: 159 | M15: =L15*D15 -> 8109 | N15: =L15/J15 -> 0.38101382 | O15: 417.30769 | P15: =O15*D15 -> 21282.692 | S15: 417.30769 | T15: =S15*D15 -> 21282.692 | W15: =ZEESHAN!W15+SAQIB!W15 -> 1550 | X15: =W15*D15 -> 79050 | Y15: =ZEESHAN!Y15+SAQIB!Y15 -> 187 | Z15: =Y15/W15 -> 0.12064516
A16: 9 | B16: Zicure 250mg Cap 10's | C16: 10's | D16: 189.25 | E16: 560 | F16: =W16/26*7 -> 779.15385 | G16: =F16*D16 -> 147454.87 | J16: 779.15385 | K16: =J16*D16 -> 147454.87 | L16: 90 | M16: =L16*D16 -> 17032.5 | N16: =L16/J16 -> 0.11550992 | O16: 779.15385 | P16: =O16*D16 -> 147454.87 | S16: 779.15385 | T16: =S16*D16 -> 147454.87 | W16: =ZEESHAN!W16+SAQIB!W16 -> 2894 | X16: =W16*D16 -> 547689.5 | Y16: =ZEESHAN!Y16+SAQIB!Y16 -> 134 | Z16: =Y16/W16 -> 0.046302695
A17: 10 | B17: Zicure 250mg Cap 6's | C17: 6's | D17: 128.86 | E17: 550 | F17: =W17/26*7 -> 765.15385 | G17: =F17*D17 -> 98597.725 | J17: 765.15385 | K17: =J17*D17 -> 98597.725 | L17: 3 | M17: =L17*D17 -> 386.58 | N17: =L17/J17 -> 0.0039207801 | O17: 765.15385 | P17: =O17*D17 -> 98597.725 | S17: 765.15385 | T17: =S17*D17 -> 98597.725 | W17: =ZEESHAN!W17+SAQIB!W17 -> 2842 | X17: =W17*D17 -> 366220.12 | Y17: =ZEESHAN!Y17+SAQIB!Y17 -> 0 | Z17: =Y17/W17 -> 0
A18: 11 | B18: Curatral 100mg Cap | C18: 4's | D18: 94.9 | E18: 650 | F18: =W18/26*7 -> 904.07692 | G18: =F18*D18 -> 85796.9 | J18: 904.07692 | K18: =J18*D18 -> 85796.9 | L18: 102 | M18: =L18*D18 -> 9679.8 | N18: =L18/J18 -> 0.11282226 | O18: 904.07692 | P18: =O18*D18 -> 85796.9 | S18: 904.07692 | T18: =S18*D18 -> 85796.9 | W18: =ZEESHAN!W18+SAQIB!W18 -> 3358 | X18: =W18*D18 -> 318674.2 | Y18: =ZEESHAN!Y18+SAQIB!Y18 -> 109 | Z18: =Y18/W18 -> 0.032459797
A19: 12 | B19: TECHFEN SR Tab 100mg | C19: 30's | D19: 85.33 | E19: 550 | F19: =W19/26*7 -> 765.15385 | G19: =F19*D19 -> 65290.578 | J19: 765.15385 | K19: =J19*D19 -> 65290.578 | L19: 312 | M19: =L19*D19 -> 26622.96 | N19: =L19/J19 -> 0.40776113 | O19: 765.15385 | P19: =O19*D19 -> 65290.578 | S19: 765.15385 | T19: =S19*D19 -> 65290.578 | W19: =ZEESHAN!W19+SAQIB!W19 -> 2842 | X19: =W19*D19 -> 242507.86 | Y19: =ZEESHAN!Y19+SAQIB!Y19 -> 419 | Z19: =Y19/W19 -> 0.14743139
... A22: 15 | B22: Pirotech 20mg Tab | C22: 20's | D22: 89.64 | E22: 300 | F22: =W22/26*7 -> 417.30769 | G22: =F22*D22 -> 37407.462 | J22: 417.30769 | K22: =J22*D22 -> 37407.462 | L22: 84 | M22: =L22*D22 -> 7529.76 | N22: =L22/J22 -> 0.20129032 | O22: 417.30769 | P22: =O22*D22 -> 37407.462 | S22: 417.30769 | T22: =S22*D22 -> 37407.462 | W22: =ZEESHAN!W22+SAQIB!W22 -> 1550 | X22: =W22*D22 -> 138942 | Y22: =ZEESHAN!Y22+SAQIB!Y22 -> 54 | Z22: =Y22/W22 -> 0.03483871
A23: Total Life Line Group Units | F23: =SUM(F8:F22) -> 7669.3077 | G23: =F23*D23 -> 0 | J23: =SUM(J8:J22) -> 7669.3077 | K23: =SUM(K8:K22) -> 833477.28 | L23: =SUM(L8:L22) -> 2331 | M23: =SUM(M8:M22) -> 247503.77 | N23: =L23/J23 -> 0.30393878 | O23: =SUM(O8:O22) -> 7669.3077 | P23: =O23*D23 -> 0 | S23: =SUM(S8:S22) -> 7669.3077 | T23: =SUM(T8:T22) -> 833477.28 | W23: =SUM(W8:W22) -> 28486 | X23: =W23*D23 -> 0 | Y23: =ZEESHAN!Y23+SAQIB!Y23 -> 5935 | Z23: =Y23/W23 -> 0.20834796
A24: Total Life Line Group Value | E24: =SUM(E8:E23) -> 5512 | F24: =G24 -> 833477.28 | G24: =SUM(G8:G23) -> 833477.28 | J24: =K23 -> 833477.28 | L24: =M23 -> 247503.77 | N24: =L24/J24 -> 0.29695323 | O24: =P24 -> 833477.28 | P24: =SUM(P8:P23) -> 833477.28 | S24: =T23 -> 833477.28 | W24: =X24 -> 3095772.8 | X24: =SUM(X8:X23) -> 3095772.8 | Y24: =ZEESHAN!Y24+SAQIB!Y24 -> 543977.51 | Z24: =Y24/W24 -> 0.17571623

Sheet vacant
A1: CURATECH PHARMA (PVT) LTD
A3: SUMMARY OF (MIO) TARGET JULY-2025
A5: EHTISHAM RAFIQ (AASM)
A6: SR.NO | B6: PRODUCT NAME | C6: PACK SIZE | D6: RATE | E6: MONTHLY PER HEAD TGT | F6: 1 TO 7 | J6: 8 TO 14 | O6: 15 T0 21 | S6: 22 TO 28 | W6: TOTAL
F7: TGT UNITS | H7: ACHI | I7: % | J7: TGT UNITS | L7: ACHI | M7: % | O7: TGT UNITS | Q7: ACHI | R7: % | S7: TGT UNITS | U7: ACHI | V7: % | W7: TGT UNITS | Y7: ACHI | AA7: %
A8: 1 | B8: Curaxone 250mg IM | C8: 1 Vial | D8: 70.79 | E8: 500 | F8: =W8/2 -> 646 | G8: =F8*D8 -> 45730.34 | J8: 646 | K8: =J8*D8 -> 45730.34 | L8: 5 | M8: =L8/J8 -> 0.0077399381 | N8: =L8*D8 -> 353.95 | O8: =W8/2 -> 646 | P8: =O8*D8 -> 45730.34 | S8: 646 | T8: =S8*D8 -> 45730.34 | W8: 1292 | X8: =W8*D8 -> 91460.68 | Y8: 15 | Z8: =Y8*D8 -> 1061.85 | AA8: =Y8/W8 -> 0.011609907
A9: 2 | B9: Curaxone 500mg IV | C9: 1 Vial | D9: 89.37 | E9: 500 | F9: =W9/2 -> 646 | G9: =F9*D9 -> 57733.02 | J9: 646 | K9: =J9*D9 -> 57733.02 | L9: 10 | M9: =L9/J9 -> 0.015479876 | N9: =L9*D9 -> 893.7 | O9: =W9/2 -> 646 | P9: =O9*D9 -> 57733.02 | S9: 646 | T9: =S9*D9 -> 57733.02 | W9: 1292 | X9: =W9*D9 -> 115466.04 | Y9: 15 | Z9: =Y9*D9 -> 1340.55 | AA9: =Y9/W9 -> 0.011609907
A10: 3 | B10: Curaxone IG IV | C10: 1 Vial | D10: 112.5 | E10: 800 | F10: =W10/2 -> 1033.5 | G10: =F10*D10 -> 116268.75 | J10: 1033.5 | K10: =J10*D10 -> 116268.75 | L10: 2151 | M10: =L10/J10 -> 2.0812772 | N10: =L10*D10 -> 241987.5 | O10: =W10/2 -> 1033.5 | P10: =O10*D10 -> 116268.75 | S10: 1033.5 | T10: =S10*D10 -> 116268.75 | W10: 2067 | X10: =W10*D10 -> 232537.5 | Y10: 3247 | Z10: =Y10*D10 -> 365287.5 | AA10: =Y10/W10 -> 1.5708757
A11: 4 | B11: Mecoline 500mcg 20's | C11: 20's | D11: 55.23 | E11: 200 | F11: =W11/2 -> 258.5 | G11: =F11*D11 -> 14276.955 | J11: 258.5 | K11: =J11*D11 -> 14276.955 | L11: 0 | M11: =L11/J11 -> 0 | N11: =L11*D11 -> 0 | O11: =W11/2 -> 258.5 | P11: =O11*D11 -> 14276.955 | S11: 258.5 | T11: =S11*D11 -> 14276.955 | W11: 517 | X11: =W11*D11 -> 28553.91 | Y11: 0 | Z11: =Y11*D11 -> 0 | AA11: =Y11/W11 -> 0
A12: 5 | B12: Mecoline 500mcg 100's | C12: 100's | D12: 192.63 | E12: 192 | F12: =W12/2 -> 248 | G12: =F12*D12 -> 47772.24 | J12: 248 | K12: =J12*D12 -> 47772.24 | L12: 10 | M12: =L12/J12 -> 0.040322581 | N12: =L12*D12 -> 1926.3 | O12: =W12/2 -> 248 | P12: =O12*D12 -> 47772.24 | S12: 248 | T12: =S12*D12 -> 47772.24 | W12: 496 | X12: =W12*D12 -> 95544.48 | Y12: 1 | Z12: =Y12*D12 -> 192.63 | AA12: =Y12/W12 -> 0.002016129
A13: 6 | B13: SUDROPROXIM TAB | C13: 100's | D13: 195 | E13: 30 | F13: =W13/2 -> 39 | G13: =F13*D13 -> 7605 | J13: 39 | K13: =J13*D13 -> 7605 | L13: 0 | M13: =L13/J13 -> 0 | N13: =L13*D13 -> 0 | O13: =W13/2 -> 39 | P13: =O13*D13 -> 7605 | S13: 39 | T13: =S13*D13 -> 7605 | W13: 78 | X13: =W13*D13 -> 15210 | Y13: 0 | Z13: =Y13*D13 -> 0 | AA13: =Y13/W13 -> 0
A14: 7 | B14: SUDROPROXIM FORTE TAB | C14: 100's | D14: 648.52 | E14: 30 | F14: =W14/2 -> 39 | G14: =F14*D14 -> 25292.28 | J14: 39 | K14: =J14*D14 -> 25292.28 | L14: 0 | M14: =L14/J14 -> 0 | N14: =L14*D14 -> 0 | O14: =W14/2 -> 39 | P14: =O14*D14 -> 25292.28 | S14: 39 | T14: =S14*D14 -> 25292.28 | W14: 78 | X14: =W14*D14 -> 50584.56 | Y14: 1 | Z14: =Y14*D14 -> 648.52 | AA14: =Y14/W14 -> 0.012820513
A15: 8 | B15: TECHFEN P Tab 50mg | C15: 20's | D15: 51 | E15: 300 | F15: =W15/2 -> 387.5 | G15: =F15*D15 -> 19762.5 | J15: 387.5 | K15: =J15*D15 -> 19762.5 | L15: 104 | M15: =L15/J15 -> 0.2683871 | N15: =L15*D15 -> 5304 | O15: =W15/2 -> 387.5 | P15: =O15*D15 -> 19762.5 | S15: 387.5 | T15: =S15*D15 -> 19762.5 | W15: 775 | X15: =W15*D15 -> 39525 | Y15: 130 | Z15: =Y15*D15 -> 6630 | AA15: =Y15/W15 -> 0.16774194
A16: 9 | B16: Zicure 250mg Cap 10's | C16: 10's | D16: 189.25 | E16: 560 | F16: =W16/2 -> 723.5 | G16: =F16*D16 -> 136922.38 | J16: 723.5 | K16: =J16*D16 -> 136922.38 | L16: 60 | M16: =L16/J16 -> 0.0829302 | N16: =L16*D16 -> 11355 | O16: =W16/2 -> 723.5 | P16: =O16*D16 -> 136922.38 | S16: 723.5 | T16: =S16*D16 -> 136922.38 | W16: 1447 | X16: =W16*D16 -> 273844.75 | Y16: 112 | Z16: =Y16*D16 -> 21196 | AA16: =Y16/W16 -> 0.07740152
A17: 10 | B17: Zicure 250mg Cap 6's | C17: 6's | D17: 128.86 | E17: 550 | F17: =W17/2 -> 710.5 | G17: =F17*D17 -> 91555.03 | J17: 710.5 | K17: =J17*D17 -> 91555.03 | L17: 0 | M17: =L17/J17 -> 0 | N17: =L17*D17 -> 0 | O17: =W17/2 -> 710.5 | P17: =O17*D17 -> 91555.03 | S17: 710.5 | T17: =S17*D17 -> 91555.03 | W17: 1421 | X17: =W17*D17 -> 183110.06 | Y17: 0 | Z17: =Y17*D17 -> 0 | AA17: =Y17/W17 -> 0
A18: 11 | B18: Curatral 100mg Cap | C18: 4's | D18: 94.9 | E18: 650 | F18: =W18/2 -> 839.5 | G18: =F18*D18 -> 79668.55 | J18: 839.5 | K18: =J18*D18 -> 79668.55 | L18: 40 | M18: =L18/J18 -> 0.047647409 | N18: =L18*D18 -> 3796 | O18: =W18/2 -> 839.5 | P18: =O18*D18 -> 79668.55 | S18: 839.5 | T18: =S18*D18 -> 79668.55 | W18: 1679 | X18: =W18*D18 -> 159337.1 | Y18: 84 | Z18: =Y18*D18 -> 7971.6 | AA18: =Y18/W18 -> 0.05002978
A19: 12 | B19: TECHFEN SR Tab 100mg | C19: 30's | D19: 85.33 | E19: 550 | F19: =W19/2 -> 710.5 | G19: =F19*D19 -> 60626.965 | J19: 710.5 | K19: =J19*D19 -> 60626.965 | L19: 45 | M19: =L19/J19 -> 0.063335679 | N19: =L19*D19 -> 3839.85 | O19: =W19/2 -> 710.5 | P19: =O19*D19 -> 60626.965 | S19: 710.5 | T19: =S19*D19 -> 60626.965 | W19: 1421 | X19: =W19*D19 -> 121253.93 | Y19: 100 | Z19: =Y19*D19 -> 8533 | AA19: =Y19/W19 -> 0.070372977
... A22: 15 | B22: Pirotech 20mg Tab | C22: 20's | D22: 89.64 | E22: 300 | F22: =W22/2 -> 387.5 | G22: =F22*D22 -> 34735.5 | J22: 387.5 | K22: =J22*D22 -> 34735.5 | L22: 37 | M22: =L22/J22 -> 0.095483871 | N22: =L22*D22 -> 3316.68 | O22: =W22/2 -> 387.5 | P22: =O22*D22 -> 34735.5 | S22: 387.5 | T22: =S22*D22 -> 34735.5 | W22: 775 | X22: =W22*D22 -> 69471 | Y22: 85 | Z22: =Y22*D22 -> 7619.4 | AA22: =Y22/W22 -> 0.10967742
A23: Total Life Line Group Units | F23: =SUM(F8:F22) -> 7121.5 | G23: =F23*D23 -> 0 | J23: =SUM(J8:J22) -> 7121.5 | K23: =SUM(K8:K22) -> 773943.19 | L23: =SUM(L8:L22) -> 2462 | M23: =L23/J23 -> 0.34571368 | N23: =SUM(N8:N22) -> 272772.98 | O23: =SUM(O8:O22) -> 7121.5 | P23: =O23*D23 -> 0 | S23: =SUM(S8:S22) -> 7121.5 | T23: =SUM(T8:T22) -> 773943.19 | W23: =SUM(W8:W22) -> 14243 | X23: =W23*D23 -> 0 | Y23: =Y22+Y21+Y20+Y19+Y18+Y17+Y16+Y15+Y14+Y13+Y12+Y11+Y10+Y9+Y8 -> 3790 | Z23: =Z22+Z21+Z20+Z19+Z18+Z17+Z16+Z15+Z14+Z13+Z12+Z11+Z10+Z9+Z8 -> 420481.05 | AA23: =Y23/W23 -> 0.26609563
A24: Total Life Line Group Value | E24: =SUM(E8:E23) -> 5512 | F24: =G24 -> 773943.19 | G24: =SUM(G8:G23) -> 773943.19 | J24: =K23 -> 773943.19 | L24: =N23 -> 272772.98 | M24: =L24/J24 -> 0.35244574 | O24: =P24 -> 773943.19 | P24: =SUM(P8:P23) -> 773943.19 | S24: =T23 -> 773943.19 | W24: =X24 -> 1547886.4 | X24: =SUM(X8:X23) -> 1547886.4 | Y24: =Z23 -> 420481.05 | AA24: =Y24/W24 -> 0.27164852

Sheet SHAHEER
A1: CURATECH PHARMA (PVT) LTD
A3: SUMMARY OF (A.ASMs) TARGET JULY-2025
A5: SHAHEER GHOUS (MIO)
A6: SR.NO | B6: PRODUCT NAME | C6: PACK SIZE | D6: RATE | E6: MONTHLY PER HEAD TGT | F6: 1 TO 7 | J6: 8 TO 14 | O6: 15 T0 21 | S6: 22 TO 28 | W6: TOTAL
F7: TGT UNITS | H7: ACHI | I7: % | J7: TGT UNITS | L7: ACHI | N7: % | O7: TGT UNITS | Q7: ACHI | R7: % | S7: TGT UNITS | U7: ACHI | V7: % | W7: TGT UNITS | Y7: ACHI | AA7: %
A8: 1 | B8: Curaxone 250mg IM | C8: 1 Vial | D8: 70.79 | E8: 500 | F8: =W8/2 -> 646 | G8: =F8*D8 -> 45730.34 | J8: 646 | K8: =J8*D8 -> 45730.34 | L8: 3 | M8: =L8*D8 -> 212.37 | N8: =L8/J8 -> 0.0046439628 | O8: =W8/2 -> 646 | P8: =O8*D8 -> 45730.34 | S8: 646 | T8: =S8*D8 -> 45730.34 | W8: 1292 | X8: =W8*D8 -> 91460.68 | Y8: 9 | Z8: =Y8*D8 -> 637.11 | AA8: =Y8/W8 -> 0.0069659443
A9: 2 | B9: Curaxone 500mg IV | C9: 1 Vial | D9: 89.37 | E9: 500 | F9: =W9/2 -> 646 | G9: =F9*D9 -> 57733.02 | J9: 646 | K9: =J9*D9 -> 57733.02 | L9: 0 | M9: =L9*D9 -> 0 | N9: =L9/J9 -> 0 | O9: =W9/2 -> 646 | P9: =O9*D9 -> 57733.02 | S9: 646 | T9: =S9*D9 -> 57733.02 | W9: 1292 | X9: =W9*D9 -> 115466.04 | Y9: 10 | Z9: =Y9*D9 -> 893.7 | AA9: =Y9/W9 -> 0.0077399381
A10: 3 | B10: Curaxone IG IV | C10: 1 Vial | D10: 112.5 | E10: 800 | F10: =W10/2 -> 1033.5 | G10: =F10*D10 -> 116268.75 | J10: 1033.5 | K10: =J10*D10 -> 116268.75 | L10: 45 | M10: =L10*D10 -> 5062.5 | N10: =L10/J10 -> 0.043541364 | O10: =W10/2 -> 1033.5 | P10: =O10*D10 -> 116268.75 | S10: 1033.5 | T10: =S10*D10 -> 116268.75 | W10: 2067 | X10: =W10*D10 -> 232537.5 | Y10: 2004 | Z10: =Y10*D10 -> 225450 | AA10: =Y10/W10 -> 0.96952105
A11: 4 | B11: Mecoline 500mcg 20's | C11: 20's | D11: 55.23 | E11: 200 | F11: =W11/2 -> 258.5 | G11: =F11*D11 -> 14276.955 | J11: 258.5 | K11: =J11*D11 -> 14276.955 | L11: 0 | M11: =L11*D11 -> 0 | N11: =L11/J11 -> 0 | O11: =W11/2 -> 258.5 | P11: =O11*D11 -> 14276.955 | S11: 258.5 | T11: =S11*D11 -> 14276.955 | W11: 517 | X11: =W11*D11 -> 28553.91 | Y11: 0 | Z11: =Y11*D11 -> 0 | AA11: =Y11/W11 -> 0
A12: 5 | B12: Mecoline 500mcg 100's | C12: 100's | D12: 192.63 | E12: 192 | F12: =W12/2 -> 248 | G12: =F12*D12 -> 47772.24 | J12: 248 | K12: =J12*D12 -> 47772.24 | L12: 0 | M12: =L12*D12 -> 0 | N12: =L12/J12 -> 0 | O12: =W12/2 -> 248 | P12: =O12*D12 -> 47772.24 | S12: 248 | T12: =S12*D12 -> 47772.24 | W12: 496 | X12: =W12*D12 -> 95544.48 | Y12: 21 | Z12: =Y12*D12 -> 4045.23 | AA12: =Y12/W12 -> 0.04233871
A13: 6 | B13: SUDROPROXIM TAB | C13: 100's | D13: 195 | E13: 30 | F13: =W13/2 -> 39 | G13: =F13*D13 -> 7605 | J13: 39 | K13: =J13*D13 -> 7605 | L13: 0 | M13: =L13*D13 -> 0 | N13: =L13/J13 -> 0 | O13: =W13/2 -> 39 | P13: =O13*D13 -> 7605 | S13: 39 | T13: =S13*D13 -> 7605 | W13: 78 | X13: =W13*D13 -> 15210 | Y13: 0 | Z13: =Y13*D13 -> 0 | AA13: =Y13/W13 -> 0
A14: 7 | B14: SUDROPROXIM FORTE TAB | C14: 100's | D14: 648.52 | E14: 30 | F14: =W14/2 -> 39 | G14: =F14*D14 -> 25292.28 | J14: 39 | K14: =J14*D14 -> 25292.28 | L14: 1 | M14: =L14*D14 -> 648.52 | N14: =L14/J14 -> 0.025641026 | O14: =W14/2 -> 39 | P14: =O14*D14 -> 25292.28 | S14: 39 | T14: =S14*D14 -> 25292.28 | W14: 78 | X14: =W14*D14 -> 50584.56 | Y14: 1 | Z14: =Y14*D14 -> 648.52 | AA14: =Y14/W14 -> 0.012820513
A15: 8 | B15: TECHFEN P Tab 50mg | C15: 20's | D15: 51 | E15: 300 | F15: =W15/2 -> 387.5 | G15: =F15*D15 -> 19762.5 | J15: 387.5 | K15: =J15*D15 -> 19762.5 | L15: 55 | M15: =L15*D15 -> 2805 | N15: =L15/J15 -> 0.14193548 | O15: =W15/2 -> 387.5 | P15: =O15*D15 -> 19762.5 | S15: 387.5 | T15: =S15*D15 -> 19762.5 | W15: 775 | X15: =W15*D15 -> 39525 | Y15: 86 | Z15: =Y15*D15 -> 4386 | AA15: =Y15/W15 -> 0.11096774
A16: 9 | B16: Zicure 250mg Cap 10's | C16: 10's | D16: 189.25 | E16: 560 | F16: =W16/2 -> 723.5 | G16: =F16*D16 -> 136922.38 | J16: 723.5 | K16: =J16*D16 -> 136922.38 | L16: 19 | M16: =L16*D16 -> 3595.75 | N16: =L16/J16 -> 0.02626123 | O16: =W16/2 -> 723.5 | P16: =O16*D16 -> 136922.38 | S16: 723.5 | T16: =S16*D16 -> 136922.38 | W16: 1447 | X16: =W16*D16 -> 273844.75 | Y16: 53 | Z16: =Y16*D16 -> 10030.25 | AA16: =Y16/W16 -> 0.036627505
A17: 10 | B17: Zicure 250mg Cap 6's | C17: 6's | D17: 128.86 | E17: 550 | F17: =W17/2 -> 710.5 | G17: =F17*D17 -> 91555.03 | J17: 710.5 | K17: =J17*D17 -> 91555.03 | L17: 0 | M17: =L17*D17 -> 0 | N17: =L17/J17 -> 0 | O17: =W17/2 -> 710.5 | P17: =O17*D17 -> 91555.03 | S17: 710.5 | T17: =S17*D17 -> 91555.03 | W17: 1421 | X17: =W17*D17 -> 183110.06 | Y17: 0 | Z17: =Y17*D17 -> 0 | AA17: =Y17/W17 -> 0
A18: 11 | B18: Curatral 100mg Cap | C18: 4's | D18: 94.9 | E18: 650 | F18: =W18/2 -> 839.5 | G18: =F18*D18 -> 79668.55 | J18: 839.5 | K18: =J18*D18 -> 79668.55 | L18: 50 | M18: =L18*D18 -> 4745 | N18: =L18/J18 -> 0.059559261 | O18: =W18/2 -> 839.5 | P18: =O18*D18 -> 79668.55 | S18: 839.5 | T18: =S18*D18 -> 79668.55 | W18: 1679 | X18: =W18*D18 -> 159337.1 | Y18: 78 | Z18: =Y18*D18 -> 7402.2 | AA18: =Y18/W18 -> 0.046456224
A19: 12 | B19: TECHFEN SR Tab 100mg | C19: 30's | D19: 85.33 | E19: 550 | F19: =W19/2 -> 710.5 | G19: =F19*D19 -> 60626.965 | J19: 710.5 | K19: =J19*D19 -> 60626.965 | L19: 100 | M19: =L19*D19 -> 8533 | N19: =L19/J19 -> 0.14074595 | O19: =W19/2 -> 710.5 | P19: =O19*D19 -> 60626.965 | S19: 710.5 | T19: =S19*D19 -> 60626.965 | W19: 1421 | X19: =W19*D19 -> 121253.93 | Y19: 127 | Z19: =Y19*D19 -> 10836.91 | AA19: =Y19/W19 -> 0.089373681
... A22: 15 | B22: Pirotech 20mg Tab | C22: 20's | D22: 89.64 | E22: 300 | F22: =W22/2 -> 387.5 | G22: =F22*D22 -> 34735.5 | J22: 387.5 | K22: =J22*D22 -> 34735.5 | L22: 137 | M22: =L22*D22 -> 12280.68 | N22: =L22/J22 -> 0.35354839 | O22: =W22/2 -> 387.5 | P22: =O22*D22 -> 34735.5 | S22: 387.5 | T22: =S22*D22 -> 34735.5 | W22: 775 | X22: =W22*D22 -> 69471 | Y22: 15 | Z22: =Y22*D22 -> 1344.6 | AA22: =Y22/W22 -> 0.019354839
A23: Total Life Line Group Units | F23: =SUM(F8:F22) -> 7121.5 | G23: =F23*D23 -> 0 | J23: =SUM(J8:J22) -> 7121.5 | K23: =SUM(K8:K22) -> 773943.19 | L23: =SUM(L8:L22) -> 410 | M23: =SUM(M8:M22) -> 37882.82 | N23: =L23/J23 -> 0.057572141 | O23: =SUM(O8:O22) -> 7121.5 | P23: =O23*D23 -> 0 | S23: =SUM(S8:S22) -> 7121.5 | T23: =SUM(T8:T22) -> 773943.19 | W23: =SUM(W8:W22) -> 14243 | X23: =W23*D23 -> 0 | Y23: =SUM(Y8:Y22) -> 2404 | Z23: =Z22+Z21+Z20+Z19+Z18+Z17+Z16+Z15+Z14+Z13+Z12+Z11+Z10+Z9+Z8 -> 265674.52 | AA23: =Y23/W23 -> 0.16878467
A24: Total Life Line Group Value | E24: =SUM(E8:E23) -> 5512 | F24: =G24 -> 773943.19 | G24: =SUM(G8:G23) -> 773943.19 | J24: =K23 -> 773943.19 | L24: =M23 -> 37882.82 | N24: =L24/J24 -> 0.048947805 | O24: =P24 -> 773943.19 | P24: =SUM(P8:P23) -> 773943.19 | S24: =T23 -> 773943.19 | W24: =X24 -> 1547886.4 | X24: =SUM(X8:X23) -> 1547886.4 | Y24: =Z23 -> 265674.52 | AA24: =Y24/W24 -> 0.17163696

Sheet EHTISHAM
A1: CURATECH PHARMA (PVT) LTD
A3: SUMMARY OF (A.ASM) TARGET JULY-2025
A5: EHTISHAM RAFIQ (A.ASM)
A6: SR.NO | B6: PRODUCT NAME | C6: PACK SIZE | D6: RATE | E6: MONTHLY PER HEAD TGT | F6: 1 TO 7 | J6: 8 TO 14 | O6: 15 T0 21 | S6: 22 TO 28 | W6: TOTAL
F7: TGT UNITS | H7: ACHI | I7: % | J7: TGT UNITS | L7: ACHI | N7: % | O7: TGT UNITS | Q7: ACHI | R7: % | S7: TGT UNITS | U7: ACHI | V7: % | W7: TGT UNITS | Y7: ACHI | Z7: %
A8: 1 | B8: Curaxone 250mg IM | C8: 1 Vial | D8: 70.79 | E8: 500 | F8: =W8/26*7 -> 695.69231 | G8: =F8*D8 -> 49248.058 | J8: 695.69231 | K8: =J8*D8 -> 49248.058 | L8: 8 | M8: =L8*D8 -> 566.32 | N8: =L8/J8 -> 0.011499337 | O8: 695.69231 | P8: =O8*D8 -> 49248.058 | S8: 695.69231 | T8: =S8*D8 -> 49248.058 | W8: =ZEESHAN!W8+SAQIB!W8 -> 2584 | X8: =W8*D8 -> 182921.36 | Y8: =SHAHEER!Y8+vacant!Y8 -> 24 | Z8: =Y8/W8 -> 0.0092879257
A9: 2 | B9: Curaxone 500mg IV | C9: 1 Vial | D9: 89.37 | E9: 500 | F9: =W9/26*7 -> 695.69231 | G9: =F9*D9 -> 62174.022 | J9: 695.69231 | K9: =J9*D9 -> 62174.022 | L9: 10 | M9: =L9*D9 -> 893.7 | N9: =L9/J9 -> 0.014374171 | O9: 695.69231 | P9: =O9*D9 -> 62174.022 | S9: 695.69231 | T9: =S9*D9 -> 62174.022 | W9: =ZEESHAN!W9+SAQIB!W9 -> 2584 | X9: =W9*D9 -> 230932.08 | Y9: =SHAHEER!Y9+vacant!Y9 -> 25 | Z9: =Y9/W9 -> 0.0096749226
A10: 3 | B10: Curaxone IG IV | C10: 1 Vial | D10: 112.5 | E10: 800 | F10: =W10/26*7 -> 1113 | G10: =F10*D10 -> 125212.5 | J10: 1113 | K10: =J10*D10 -> 125212.5 | L10: 2196 | M10: =L10*D10 -> 247050 | N10: =L10/J10 -> 1.9730458 | O10: 1113 | P10: =O10*D10 -> 125212.5 | S10: 1113 | T10: =S10*D10 -> 125212.5 | W10: =ZEESHAN!W10+SAQIB!W10 -> 4134 | X10: =W10*D10 -> 465075 | Y10: =SHAHEER!Y10+vacant!Y10 -> 5251 | Z10: =Y10/W10 -> 1.2701984
A11: 4 | B11: Mecoline 500mcg 20's | C11: 20's | D11: 55.23 | E11: 200 | F11: =W11/26*7 -> 278.38462 | G11: =F11*D11 -> 15375.182 | J11: 278.38462 | K11: =J11*D11 -> 15375.182 | L11: 0 | M11: =L11*D11 -> 0 | N11: =L11/J11 -> 0 | O11: 278.38462 | P11: =O11*D11 -> 15375.182 | S11: 278.38462 | T11: =S11*D11 -> 15375.182 | W11: =ZEESHAN!W11+SAQIB!W11 -> 1034 | X11: =W11*D11 -> 57107.82 | Y11: =SHAHEER!Y11+vacant!Y11 -> 0 | Z11: =Y11/W11 -> 0
A12: 5 | B12: Mecoline 500mcg 100's | C12: 100's | D12: 192.63 | E12: 192 | F12: =W12/26*7 -> 267.07692 | G12: =F12*D12 -> 51447.028 | J12: 267.07692 | K12: =J12*D12 -> 51447.028 | L12: 10 | M12: =L12*D12 -> 1926.3 | N12: =L12/J12 -> 0.037442396 | O12: 267.07692 | P12: =O12*D12 -> 51447.028 | S12: 267.07692 | T12: =S12*D12 -> 51447.028 | W12: =ZEESHAN!W12+SAQIB!W12 -> 992 | X12: =W12*D12 -> 191088.96 | Y12: =SHAHEER!Y12+vacant!Y12 -> 22 | Z12: =Y12/W12 -> 0.022177419
A13: 6 | B13: SUDROPROXIM TAB | C13: 100's | D13: 195 | E13: 30 | F13: =W13/26*7 -> 42 | G13: =F13*D13 -> 8190 | J13: 42 | K13: =J13*D13 -> 8190 | L13: 0 | M13: =L13*D13 -> 0 | N13: =L13/J13 -> 0 | O13: 42 | P13: =O13*D13 -> 8190 | S13: 42 | T13: =S13*D13 -> 8190 | W13: =ZEESHAN!W13+SAQIB!W13 -> 156 | X13: =W13*D13 -> 30420 | Y13: =SHAHEER!Y13+vacant!Y13 -> 0 | Z13: =Y13/W13 -> 0
A14: 7 | B14: SUDROPROXIM FORTE TAB | C14: 100's | D14: 648.52 | E14: 30 | F14: =W14/26*7 -> 42 | G14: =F14*D14 -> 27237.84 | J14: 42 | K14: =J14*D14 -> 27237.84 | L14: 1 | M14: =L14*D14 -> 648.52 | N14: =L14/J14 -> 0.023809524 | O14: 42 | P14: =O14*D14 -> 27237.84 | S14: 42 | T14: =S14*D14 -> 27237.84 | W14: =ZEESHAN!W14+SAQIB!W14 -> 156 | X14: =W14*D14 -> 101169.12 | Y14: =SHAHEER!Y14+vacant!Y14 -> 2 | Z14: =Y14/W14 -> 0.012820513
A15: 8 | B15: TECHFEN P Tab 50mg | C15: 20's | D15: 51 | E15: 300 | F15: =W15/26*7 -> 417.30769 | G15: =F15*D15 -> 21282.692 | J15: 417.30769 | K15: =J15*D15 -> 21282.692 | L15: 159 | M15: =L15*D15 -> 8109 | N15: =L15/J15 -> 0.38101382 | O15: 417.30769 | P15: =O15*D15 -> 21282.692 | S15: 417.30769 | T15: =S15*D15 -> 21282.692 | W15: =ZEESHAN!W15+SAQIB!W15 -> 1550 | X15: =W15*D15 -> 79050 | Y15: =SHAHEER!Y15+vacant!Y15 -> 216 | Z15: =Y15/W15 -> 0.13935484
A16: 9 | B16: Zicure 250mg Cap 10's | C16: 10's | D16: 189.25 | E16: 560 | F16: =W16/26*7 -> 779.15385 | G16: =F16*D16 -> 147454.87 | J16: 779.15385 | K16: =J16*D16 -> 147454.87 | L16: 79 | M16: =L16*D16 -> 14950.75 | N16: =L16/J16 -> 0.10139204 | O16: 779.15385 | P16: =O16*D16 -> 147454.87 | S16: 779.15385 | T16: =S16*D16 -> 147454.87 | W16: =ZEESHAN!W16+SAQIB!W16 -> 2894 | X16: =W16*D16 -> 547689.5 | Y16: =SHAHEER!Y16+vacant!Y16 -> 165 | Z16: =Y16/W16 -> 0.057014513
A17: 10 | B17: Zicure 250mg Cap 6's | C17: 6's | D17: 128.86 | E17: 550 | F17: =W17/26*7 -> 765.15385 | G17: =F17*D17 -> 98597.725 | J17: 765.15385 | K17: =J17*D17 -> 98597.725 | L17: 0 | M17: =L17*D17 -> 0 | N17: =L17/J17 -> 0 | O17: 765.15385 | P17: =O17*D17 -> 98597.725 | S17: 765.15385 | T17: =S17*D17 -> 98597.725 | W17: =ZEESHAN!W17+SAQIB!W17 -> 2842 | X17: =W17*D17 -> 366220.12 | Y17: =SHAHEER!Y17+vacant!Y17 -> 0 | Z17: =Y17/W17 -> 0
A18: 11 | B18: Curatral 100mg Cap | C18: 4's | D18: 94.9 | E18: 650 | F18: =W18/26*7 -> 904.07692 | G18: =F18*D18 -> 85796.9 | J18: 904.07692 | K18: =J18*D18 -> 85796.9 | L18: 90 | M18: =L18*D18 -> 8541 | N18: =L18/J18 -> 0.099549051 | O18: 904.07692 | P18: =O18*D18 -> 85796.9 | S18: 904.07692 | T18: =S18*D18 -> 85796.9 | W18: =ZEESHAN!W18+SAQIB!W18 -> 3358 | X18: =W18*D18 -> 318674.2 | Y18: =SHAHEER!Y18+vacant!Y18 -> 162 | Z18: =Y18/W18 -> 0.048243002
A19: 12 | B19: TECHFEN SR Tab 100mg | C19: 30's | D19: 85.33 | E19: 550 | F19: =W19/26*7 -> 765.15385 | G19: =F19*D19 -> 65290.578 | J19: 765.15385 | K19: =J19*D19 -> 65290.578 | L19: 145 | M19: =L19*D19 -> 12372.85 | N19: =L19/J19 -> 0.18950437 | O19: 765.15385 | P19: =O19*D19 -> 65290.578 | S19: 765.15385 | T19: =S19*D19 -> 65290.578 | W19: =ZEESHAN!W19+SAQIB!W19 -> 2842 | X19: =W19*D19 -> 242507.86 | Y19: =SHAHEER!Y19+vacant!Y19 -> 227 | Z19: =Y19/W19 -> 0.079873329
... A22: 15 | B22: Pirotech 20mg Tab | C22: 20's | D22: 89.64 | E22: 300 | F22: =W22/26*7 -> 417.30769 | G22: =F22*D22 -> 37407.462 | J22: 417.30769 | K22: =J22*D22 -> 37407.462 | L22: 174 | M22: =L22*D22 -> 15597.36 | N22: =L22/J22 -> 0.41695853 | O22: 417.30769 | P22: =O22*D22 -> 37407.462 | S22: 417.30769 | T22: =S22*D22 -> 37407.462 | W22: =ZEESHAN!W22+SAQIB!W22 -> 1550 | X22: =W22*D22 -> 138942 | Y22: =SHAHEER!Y22+vacant!Y22 -> 100 | Z22: =Y22/W22 -> 0.064516129
A23: Total Life Line Group Units | F23: =SUM(F8:F22) -> 7669.3077 | G23: =F23*D23 -> 0 | J23: =SUM(J8:J22) -> 7669.3077 | K23: =SUM(K8:K22) -> 833477.28 | L23: =SUM(L8:L22) -> 2872 | M23: =SUM(M8:M22) -> 310655.8 | N23: =L23/J23 -> 0.37447969 | O23: =SUM(O8:O22) -> 7669.3077 | P23: =O23*D23 -> 0 | S23: =SUM(S8:S22) -> 7669.3077 | T23: =SUM(T8:T22) -> 833477.28 | W23: =SUM(W8:W22) -> 28486 | X23: =W23*D23 -> 0 | Y23: =SHAHEER!Y23+vacant!Y23 -> 6194 | Z23: =Y23/W23 -> 0.21744015
A24: Total Life Line Group Value | E24: =SUM(E8:E23) -> 5512 | F24: =G24 -> 833477.28 | G24: =SUM(G8:G23) -> 833477.28 | J24: =K23 -> 833477.28 | L24: =M23 -> 310655.8 | N24: =L24/J24 -> 0.37272258 | O24: =P24 -> 833477.28 | P24: =SUM(P8:P23) -> 833477.28 | S24: =T23 -> 833477.28 | W24: =X24 -> 3095772.8 | X24: =SUM(X8:X23) -> 3095772.8 | Y24: =SHAHEER!Y24+vacant!Y24 -> 686155.57 | Z24: =Y24/W24 -> 0.22164274

Sheet NAFEES
A1: CURATECH PHARMA (PVT) LTD
A3: SUMMARY OF (MIO) TARGET August-2025
A5: NAFEES (MIO)
A6: SR.NO | B6: PRODUCT NAME | C6: PACK SIZE | D6: RATE | E6: MONTHLY PER HEAD TGT | F6: 1 TO 7 | J6: 8 TO 14 | O6: 15 T0 21 | S6: 22 TO 28 | W6: TOTAL
F7: TGT UNITS | H7: ACHI | I7: % | J7: TGT UNITS | L7: ACHI | N7: % | O7: TGT UNITS | Q7: ACHI | R7: % | S7: TGT UNITS | U7: ACHI | V7: % | W7: TGT UNITS | Y7: ACHI | AA7: %
A8: 1 | B8: Curaxone 250mg IM | C8: 1 Vial | D8: 70.79 | E8: 500 | F8: =W8/2 -> 646 | G8: =F8*D8 -> 45730.34 | J8: 646 | K8: =J8*D8 -> 45730.34 | L8: 0 | M8: =L8*D8 -> 0 | N8: =L8/J8 -> 0 | O8: =W8/2 -> 646 | P8: =O8*D8 -> 45730.34 | S8: 646 | T8: =S8*D8 -> 45730.34 | W8: 1292 | X8: =W8*D8 -> 91460.68 | Y8: 55 | Z8: =Y8*D8 -> 3893.45 | AA8: =Y8/W8 -> 0.042569659
A9: 2 | B9: Curaxone 500mg IV | C9: 1 Vial | D9: 89.37 | E9: 500 | F9: =W9/2 -> 646 | G9: =F9*D9 -> 57733.02 | J9: 646 | K9: =J9*D9 -> 57733.02 | L9: 0 | M9: =L9*D9 -> 0 | N9: =L9/J9 -> 0 | O9: =W9/2 -> 646 | P9: =O9*D9 -> 57733.02 | S9: 646 | T9: =S9*D9 -> 57733.02 | W9: 1292 | X9: =W9*D9 -> 115466.04 | Y9: 45 | Z9: =Y9*D9 -> 4021.65 | AA9: =Y9/W9 -> 0.034829721
A10: 3 | B10: Curaxone IG IV | C10: 1 Vial | D10: 112.5 | E10: 800 | F10: =W10/2 -> 1033.5 | G10: =F10*D10 -> 116268.75 | J10: 1033.5 | K10: =J10*D10 -> 116268.75 | L10: 624 | M10: =L10*D10 -> 70200 | N10: =L10/J10 -> 0.60377358 | O10: =W10/2 -> 1033.5 | P10: =O10*D10 -> 116268.75 | S10: 1033.5 | T10: =S10*D10 -> 116268.75 | W10: 2067 | X10: =W10*D10 -> 232537.5 | Y10: 944 | Z10: =Y10*D10 -> 106200 | AA10: =Y10/W10 -> 0.45670053
A11: 4 | B11: Mecoline 500mcg 20's | C11: 20's | D11: 55.23 | E11: 200 | F11: =W11/2 -> 258.5 | G11: =F11*D11 -> 14276.955 | J11: 258.5 | K11: =J11*D11 -> 14276.955 | L11: 0 | M11: =L11*D11 -> 0 | N11: =L11/J11 -> 0 | O11: =W11/2 -> 258.5 | P11: =O11*D11 -> 14276.955 | S11: 258.5 | T11: =S11*D11 -> 14276.955 | W11: 517 | X11: =W11*D11 -> 28553.91 | Y11: 0 | Z11: =Y11*D11 -> 0 | AA11: =Y11/W11 -> 0
A12: 5 | B12: Mecoline 500mcg 100's | C12: 100's | D12: 192.63 | E12: 192 | F12: =W12/2 -> 248 | G12: =F12*D12 -> 47772.24 | J12: 248 | K12: =J12*D12 -> 47772.24 | L12: 1 | M12: =L12*D12 -> 192.63 | N12: =L12/J12 -> 0.0040322581 | O12: =W12/2 -> 248 | P12: =O12*D12 -> 47772.24 | S12: 248 | T12: =S12*D12 -> 47772.24 | W12: 496 | X12: =W12*D12 -> 95544.48 | Y12: 9 | Z12: =Y12*D12 -> 1733.67 | AA12: =Y12/W12 -> 0.018145161
A13: 6 | B13: SUDROPROXIM TAB | C13: 100's | D13: 195 | E13: 30 | F13: =W13/2 -> 39 | G13: =F13*D13 -> 7605 | J13: 39 | K13: =J13*D13 -> 7605 | L13: 0 | M13: =L13*D13 -> 0 | N13: =L13/J13 -> 0 | O13: =W13/2 -> 39 | P13: =O13*D13 -> 7605 | S13: 39 | T13: =S13*D13 -> 7605 | W13: 78 | X13: =W13*D13 -> 15210 | Y13: 0 | Z13: =Y13*D13 -> 0 | AA13: =Y13/W13 -> 0
A14: 7 | B14: SUDROPROXIM FORTE TAB | C14: 100's | D14: 648.52 | E14: 30 | F14: =W14/2 -> 39 | G14: =F14*D14 -> 25292.28 | J14: 39 | K14: =J14*D14 -> 25292.28 | L14: 0 | M14: =L14*D14 -> 0 | N14: =L14/J14 -> 0 | O14: =W14/2 -> 39 | P14: =O14*D14 -> 25292.28 | S14: 39 | T14: =S14*D14 -> 25292.28 | W14: 78 | X14: =W14*D14 -> 50584.56 | Y14: 0 | Z14: =Y14*D14 -> 0 | AA14: =Y14/W14 -> 0
A15: 8 | B15: TECHFEN P Tab 50mg | C15: 20's | D15: 51 | E15: 300 | F15: =W15/2 -> 387.5 | G15: =F15*D15 -> 19762.5 | J15: 387.5 | K15: =J15*D15 -> 19762.5 | L15: 12 | M15: =L15*D15 -> 612 | N15: =L15/J15 -> 0.030967742 | O15: =W15/2 -> 387.5 | P15: =O15*D15 -> 19762.5 | S15: 387.5 | T15: =S15*D15 -> 19762.5 | W15: 775 | X15: =W15*D15 -> 39525 | Y15: 15 | Z15: =Y15*D15 -> 765 | AA15: =Y15/W15 -> 0.019354839
A16: 9 | B16: Zicure 250mg Cap 10's | C16: 10's | D16: 189.25 | E16: 560 | F16: =W16/2 -> 723.5 | G16: =F16*D16 -> 136922.38 | J16: 723.5 | K16: =J16*D16 -> 136922.38 | L16: 8 | M16: =L16*D16 -> 1514 | N16: =L16/J16 -> 0.01105736 | O16: =W16/2 -> 723.5 | P16: =O16*D16 -> 136922.38 | S16: 723.5 | T16: =S16*D16 -> 136922.38 | W16: 1447 | X16: =W16*D16 -> 273844.75 | Y16: 23 | Z16: =Y16*D16 -> 4352.75 | AA16: =Y16/W16 -> 0.015894955
A17: 10 | B17: Zicure 250mg Cap 6's | C17: 6's | D17: 128.86 | E17: 550 | F17: =W17/2 -> 710.5 | G17: =F17*D17 -> 91555.03 | J17: 710.5 | K17: =J17*D17 -> 91555.03 | L17: 0 | M17: =L17*D17 -> 0 | N17: =L17/J17 -> 0 | O17: =W17/2 -> 710.5 | P17: =O17*D17 -> 91555.03 | S17: 710.5 | T17: =S17*D17 -> 91555.03 | W17: 1421 | X17: =W17*D17 -> 183110.06 | Y17: 0 | Z17: =Y17*D17 -> 0 | AA17: =Y17/W17 -> 0
A18: 11 | B18: Curatral 100mg Cap | C18: 4's | D18: 94.9 | E18: 650 | F18: =W18/2 -> 839.5 | G18: =F18*D18 -> 79668.55 | J18: 839.5 | K18: =J18*D18 -> 79668.55 | L18: 49 | M18: =L18*D18 -> 4650.1 | N18: =L18/J18 -> 0.058368076 | O18: =W18/2 -> 839.5 | P18: =O18*D18 -> 79668.55 | S18: 839.5 | T18: =S18*D18 -> 79668.55 | W18: 1679 | X18: =W18*D18 -> 159337.1 | Y18: 112 | Z18: =Y18*D18 -> 10628.8 | AA18: =Y18/W18 -> 0.066706373
A19: 12 | B19: TECHFEN SR Tab 100mg | C19: 30's | D19: 85.33 | E19: 550 | F19: =W19/2 -> 710.5 | G19: =F19*D19 -> 60626.965 | J19: 710.5 | K19: =J19*D19 -> 60626.965 | L19: 400 | M19: =L19*D19 -> 34132 | N19: =L19/J19 -> 0.56298381 | O19: =W19/2 -> 710.5 | P19: =O19*D19 -> 60626.965 | S19: 710.5 | T19: =S19*D19 -> 60626.965 | W19: 1421 | X19: =W19*D19 -> 121253.93 | Y19: 388 | Z19: =Y19*D19 -> 33108.04 | AA19: =Y19/W19 -> 0.27304715
... A22: 15 | B22: Pirotech 20mg Tab | C22: 20's | D22: 89.64 | E22: 300 | F22: =W22/2 -> 387.5 | G22: =F22*D22 -> 34735.5 | J22: 387.5 | K22: =J22*D22 -> 34735.5 | L22: 18 | M22: =L22*D22 -> 1613.52 | N22: =L22/J22 -> 0.046451613 | O22: =W22/2 -> 387.5 | P22: =O22*D22 -> 34735.5 | S22: 387.5 | T22: =S22*D22 -> 34735.5 | W22: 775 | X22: =W22*D22 -> 69471 | Y22: 55 | Z22: =Y22*D22 -> 4930.2 | AA22: =Y22/W22 -> 0.070967742
A23: Total Life Line Group Units | F23: =SUM(F8:F22) -> 7121.5 | G23: =F23*D23 -> 0 | J23: =SUM(J8:J22) -> 7121.5 | K23: =SUM(K8:K22) -> 773943.19 | L23: =SUM(L8:L22) -> 1112 | M23: =SUM(M8:M22) -> 112914.25 | N23: =L23/J23 -> 0.15614688 | O23: =SUM(O8:O22) -> 7121.5 | P23: =O23*D23 -> 0 | S23: =SUM(S8:S22) -> 7121.5 | T23: =SUM(T8:T22) -> 773943.19 | W23: =SUM(W8:W22) -> 14243 | X23: =W23*D23 -> 0 | Y23: =SUM(Y8:Y22) -> 1646 | AA23: =Y23/W23 -> 0.11556554
A24: Total Life Line Group Value | E24: =SUM(E8:E23) -> 5512 | F24: =G24 -> 773943.19 | G24: =SUM(G8:G23) -> 773943.19 | J24: =K23 -> 773943.19 | L24: =M23 -> 112914.25 | N24: =L24/J24 -> 0.14589475 | O24: =P24 -> 773943.19 | P24: =SUM(P8:P23) -> 773943.19 | S24: =T23 -> 773943.19 | W24: =X24 -> 1547886.4 | X24: =SUM(X8:X23) -> 1547886.4 | AA24: =Y24/W24 -> 0

Sheet TOUSEEF
A1: CURATECH PHARMA (PVT) LTD
A3: SUMMARY OF (A.ASMs) TARGET JULY-2025
A5: TOUSEEF (MIO)
A6: SR.NO | B6: PRODUCT NAME | C6: PACK SIZE | D6: RATE | E6: MONTHLY PER HEAD TGT | F6: 1 TO 7 | J6: 8 TO 14 | O6: 15 T0 21 | S6: 22 TO 28 | W6: TOTAL
F7: TGT UNITS | H7: ACHI | I7: % | J7: TGT UNITS | L7: ACHI | N7: % | O7: TGT UNITS | Q7: ACHI | R7: % | S7: TGT UNITS | U7: ACHI | V7: % | W7: TGT UNITS | Y7: ACHI | AA7: %
A8: 1 | B8: Curaxone 250mg IM | C8: 1 Vial | D8: 70.79 | E8: 500 | F8: =W8/2 -> 646 | G8: =F8*D8 -> 45730.34 | J8: 646 | K8: =J8*D8 -> 45730.34 | L8: 0 | M8: =L8*D8 -> 0 | N8: =L8/J8 -> 0 | O8: =W8/2 -> 646 | P8: =O8*D8 -> 45730.34 | S8: 646 | T8: =S8*D8 -> 45730.34 | W8: 1292 | X8: =W8*D8 -> 91460.68 | Y8: 80 | Z8: =Y8*D8 -> 5663.2 | AA8: =Y8/W8 -> 0.061919505
A9: 2 | B9: Curaxone 500mg IV | C9: 1 Vial | D9: 89.37 | E9: 500 | F9: =W9/2 -> 646 | G9: =F9*D9 -> 57733.02 | J9: 646 | K9: =J9*D9 -> 57733.02 | L9: 50 | M9: =L9*D9 -> 4468.5 | N9: =L9/J9 -> 0.077399381 | O9: =W9/2 -> 646 | P9: =O9*D9 -> 57733.02 | S9: 646 | T9: =S9*D9 -> 57733.02 | W9: 1292 | X9: =W9*D9 -> 115466.04 | Y9: 30 | Z9: =Y9*D9 -> 2681.1 | AA9: =Y9/W9 -> 0.023219814
A10: 3 | B10: Curaxone IG IV | C10: 1 Vial | D10: 112.5 | E10: 800 | F10: =W10/2 -> 1033.5 | G10: =F10*D10 -> 116268.75 | J10: 1033.5 | K10: =J10*D10 -> 116268.75 | L10: 616 | M10: =L10*D10 -> 69300 | N10: =L10/J10 -> 0.5960329 | O10: =W10/2 -> 1033.5 | P10: =O10*D10 -> 116268.75 | S10: 1033.5 | T10: =S10*D10 -> 116268.75 | W10: 2067 | X10: =W10*D10 -> 232537.5 | Y10: 1450 | Z10: =Y10*D10 -> 163125 | AA10: =Y10/W10 -> 0.70149976
A11: 4 | B11: Mecoline 500mcg 20's | C11: 20's | D11: 55.23 | E11: 200 | F11: =W11/2 -> 258.5 | G11: =F11*D11 -> 14276.955 | J11: 258.5 | K11: =J11*D11 -> 14276.955 | L11: 0 | M11: =L11*D11 -> 0 | N11: =L11/J11 -> 0 | O11: =W11/2 -> 258.5 | P11: =O11*D11 -> 14276.955 | S11: 258.5 | T11: =S11*D11 -> 14276.955 | W11: 517 | X11: =W11*D11 -> 28553.91 | Y11: 0 | Z11: =Y11*D11 -> 0 | AA11: =Y11/W11 -> 0
A12: 5 | B12: Mecoline 500mcg 100's | C12: 100's | D12: 192.63 | E12: 192 | F12: =W12/2 -> 248 | G12: =F12*D12 -> 47772.24 | J12: 248 | K12: =J12*D12 -> 47772.24 | L12: 8 | M12: =L12*D12 -> 1541.04 | N12: =L12/J12 -> 0.032258065 | O12: =W12/2 -> 248 | P12: =O12*D12 -> 47772.24 | S12: 248 | T12: =S12*D12 -> 47772.24 | W12: 496 | X12: =W12*D12 -> 95544.48 | Y12: 8 | Z12: =Y12*D12 -> 1541.04 | AA12: =Y12/W12 -> 0.016129032
A13: 6 | B13: SUDROPROXIM TAB | C13: 100's | D13: 195 | E13: 30 | F13: =W13/2 -> 39 | G13: =F13*D13 -> 7605 | J13: 39 | K13: =J13*D13 -> 7605 | L13: 0 | M13: =L13*D13 -> 0 | N13: =L13/J13 -> 0 | O13: =W13/2 -> 39 | P13: =O13*D13 -> 7605 | S13: 39 | T13: =S13*D13 -> 7605 | W13: 78 | X13: =W13*D13 -> 15210 | Y13: 0 | Z13: =Y13*D13 -> 0 | AA13: =Y13/W13 -> 0
A14: 7 | B14: SUDROPROXIM FORTE TAB | C14: 100's | D14: 648.52 | E14: 30 | F14: =W14/2 -> 39 | G14: =F14*D14 -> 25292.28 | J14: 39 | K14: =J14*D14 -> 25292.28 | L14: 10 | M14: =L14*D14 -> 6485.2 | N14: =L14/J14 -> 0.25641026 | O14: =W14/2 -> 39 | P14: =O14*D14 -> 25292.28 | S14: 39 | T14: =S14*D14 -> 25292.28 | W14: 78 | X14: =W14*D14 -> 50584.56 | Y14: 0 | Z14: =Y14*D14 -> 0 | AA14: =Y14/W14 -> 0
A15: 8 | B15: TECHFEN P Tab 50mg | C15: 20's | D15: 51 | E15: 300 | F15: =W15/2 -> 387.5 | G15: =F15*D15 -> 19762.5 | J15: 387.5 | K15: =J15*D15 -> 19762.5 | L15: 23 | M15: =L15*D15 -> 1173 | N15: =L15/J15 -> 0.059354839 | O15: =W15/2 -> 387.5 | P15: =O15*D15 -> 19762.5 | S15: 387.5 | T15: =S15*D15 -> 19762.5 | W15: 775 | X15: =W15*D15 -> 39525 | Y15: 111 | Z15: =Y15*D15 -> 5661 | AA15: =Y15/W15 -> 0.14322581
A16: 9 | B16: Zicure 250mg Cap 10's | C16: 10's | D16: 189.25 | E16: 560 | F16: =W16/2 -> 723.5 | G16: =F16*D16 -> 136922.38 | J16: 723.5 | K16: =J16*D16 -> 136922.38 | L16: 3 | M16: =L16*D16 -> 567.75 | N16: =L16/J16 -> 0.00414651 | O16: =W16/2 -> 723.5 | P16: =O16*D16 -> 136922.38 | S16: 723.5 | T16: =S16*D16 -> 136922.38 | W16: 1447 | X16: =W16*D16 -> 273844.75 | Y16: 84 | Z16: =Y16*D16 -> 15897 | AA16: =Y16/W16 -> 0.05805114
A17: 10 | B17: Zicure 250mg Cap 6's | C17: 6's | D17: 128.86 | E17: 550 | F17: =W17/2 -> 710.5 | G17: =F17*D17 -> 91555.03 | J17: 710.5 | K17: =J17*D17 -> 91555.03 | L17: 0 | M17: =L17*D17 -> 0 | N17: =L17/J17 -> 0 | O17: =W17/2 -> 710.5 | P17: =O17*D17 -> 91555.03 | S17: 710.5 | T17: =S17*D17 -> 91555.03 | W17: 1421 | X17: =W17*D17 -> 183110.06 | Y17: 0 | Z17: =Y17*D17 -> 0 | AA17: =Y17/W17 -> 0
A18: 11 | B18: Curatral 100mg Cap | C18: 4's | D18: 94.9 | E18: 650 | F18: =W18/2 -> 839.5 | G18: =F18*D18 -> 79668.55 | J18: 839.5 | K18: =J18*D18 -> 79668.55 | L18: 10 | M18: =L18*D18 -> 949 | N18: =L18/J18 -> 0.011911852 | O18: =W18/2 -> 839.5 | P18: =O18*D18 -> 79668.55 | S18: 839.5 | T18: =S18*D18 -> 79668.55 | W18: 1679 | X18: =W18*D18 -> 159337.1 | Y18: 195 | Z18: =Y18*D18 -> 18505.5 | AA18: =Y18/W18 -> 0.11614056
A19: 12 | B19: TECHFEN SR Tab 100mg | C19: 30's | D19: 85.33 | E19: 550 | F19: =W19/2 -> 710.5 | G19: =F19*D19 -> 60626.965 | J19: 710.5 | K19: =J19*D19 -> 60626.965 | L19: 177 | M19: =L19*D19 -> 15103.41 | N19: =L19/J19 -> 0.24912034 | O19: =W19/2 -> 710.5 | P19: =O19*D19 -> 60626.965 | S19: 710.5 | T19: =S19*D19 -> 60626.965 | W19: 1421 | X19: =W19*D19 -> 121253.93 | Y19: 430 | Z19: =Y19*D19 -> 36691.9 | AA19: =Y19/W19 -> 0.3026038
... A22: 15 | B22: Pirotech 20mg Tab | C22: 20's | D22: 89.64 | E22: 300 | F22: =W22/2 -> 387.5 | G22: =F22*D22 -> 34735.5 | J22: 387.5 | K22: =J22*D22 -> 34735.5 | L22: 95 | M22: =L22*D22 -> 8515.8 | N22: =L22/J22 -> 0.24516129 | O22: =W22/2 -> 387.5 | P22: =O22*D22 -> 34735.5 | S22: 387.5 | T22: =S22*D22 -> 34735.5 | W22: 775 | X22: =W22*D22 -> 69471 | Y22: 115 | Z22: =Y22*D22 -> 10308.6 | AA22: =Y22/W22 -> 0.1483871
A23: Total Life Line Group Units | F23: =SUM(F8:F22) -> 7121.5 | G23: =F23*D23 -> 0 | J23: =SUM(J8:J22) -> 7121.5 | K23: =SUM(K8:K22) -> 773943.19 | L23: =SUM(L8:L22) -> 992 | M23: =SUM(M8:M22) -> 108103.7 | N23: =L23/J23 -> 0.1392965 | O23: =SUM(O8:O22) -> 7121.5 | P23: =O23*D23 -> 0 | S23: =SUM(S8:S22) -> 7121.5 | T23: =SUM(T8:T22) -> 773943.19 | W23: =SUM(W8:W22) -> 14243 | X23: =W23*D23 -> 0 | Y23: 2503 | AA23: =Y23/W23 -> 0.17573545
A24: Total Life Line Group Value | E24: =SUM(E8:E23) -> 5512 | F24: =G24 -> 773943.19 | G24: =SUM(G8:G23) -> 773943.19 | J24: =K23 -> 773943.19 | L24: =M23 -> 108103.7 | N24: =L24/J24 -> 0.13967912 | O24: =P24 -> 773943.19 | P24: =SUM(P8:P23) -> 773943.19 | S24: =T23 -> 773943.19 | W24: =X24 -> 1547886.4 | X24: =SUM(X8:X23) -> 1547886.4 | AA24: =Y24/W24 -> 0

Sheet AYAZ
A1: CURATECH PHARMA (PVT) LTD
A3: SUMMARY OF (A.ASM) TARGET JULY-2025
A5: AYAZ LARIK (A.ASM)
A6: SR.NO | B6: PRODUCT NAME | C6: PACK SIZE | D6: RATE | E6: MONTHLY PER HEAD TGT | F6: 1 TO 7 | J6: 8 TO 14 | O6: 15 T0 21 | S6: 22 TO 28 | W6: TOTAL
F7: TGT UNITS | H7: ACHI | I7: % | J7: TGT UNITS | L7: ACHI | N7: % | O7: TGT UNITS | Q7: ACHI | R7: % | S7: TGT UNITS | U7: ACHI | V7: % | W7: TGT UNITS | Y7: ACHI | Z7: %
A8: 1 | B8: Curaxone 250mg IM | C8: 1 Vial | D8: 70.79 | E8: 500 | F8: =W8/26*7 -> 695.69231 | G8: =F8*D8 -> 49248.058 | J8: 695.69231 | K8: =J8*D8 -> 49248.058 | L8: 10 | M8: =L8*D8 -> 707.9 | N8: =L8/J8 -> 0.014374171 | O8: 695.69231 | P8: =O8*D8 -> 49248.058 | S8: 695.69231 | T8: =S8*D8 -> 49248.058 | W8: =ZEESHAN!W8+SAQIB!W8 -> 2584 | X8: =W8*D8 -> 182921.36 | Y8: 120 | Z8: =Y8/W8 -> 0.046439628
A9: 2 | B9: Curaxone 500mg IV | C9: 1 Vial | D9: 89.37 | E9: 500 | F9: =W9/26*7 -> 695.69231 | G9: =F9*D9 -> 62174.022 | J9: 695.69231 | K9: =J9*D9 -> 62174.022 | L9: 50 | M9: =L9*D9 -> 4468.5 | N9: =L9/J9 -> 0.071870854 | O9: 695.69231 | P9: =O9*D9 -> 62174.022 | S9: 695.69231 | T9: =S9*D9 -> 62174.022 | W9: =ZEESHAN!W9+SAQIB!W9 -> 2584 | X9: =W9*D9 -> 230932.08 | Y9: 40 | Z9: =Y9/W9 -> 0.015479876
A10: 3 | B10: Curaxone IG IV | C10: 1 Vial | D10: 112.5 | E10: 800 | F10: =W10/26*7 -> 1113 | G10: =F10*D10 -> 125212.5 | J10: 1113 | K10: =J10*D10 -> 125212.5 | L10: 1205 | M10: =L10*D10 -> 135562.5 | N10: =L10/J10 -> 1.0826595 | O10: 1113 | P10: =O10*D10 -> 125212.5 | S10: 1113 | T10: =S10*D10 -> 125212.5 | W10: =ZEESHAN!W10+SAQIB!W10 -> 4134 | X10: =W10*D10 -> 465075 | Y10: 2338 | Z10: =Y10/W10 -> 0.56555394
A11: 4 | B11: Mecoline 500mcg 20's | C11: 20's | D11: 55.23 | E11: 200 | F11: =W11/26*7 -> 278.38462 | G11: =F11*D11 -> 15375.182 | J11: 278.38462 | K11: =J11*D11 -> 15375.182 | L11: 0 | M11: =L11*D11 -> 0 | N11: =L11/J11 -> 0 | O11: 278.38462 | P11: =O11*D11 -> 15375.182 | S11: 278.38462 | T11: =S11*D11 -> 15375.182 | W11: =ZEESHAN!W11+SAQIB!W11 -> 1034 | X11: =W11*D11 -> 57107.82 | Y11: 0 | Z11: =Y11/W11 -> 0
A12: 5 | B12: Mecoline 500mcg 100's | C12: 100's | D12: 192.63 | E12: 192 | F12: =W12/26*7 -> 267.07692 | G12: =F12*D12 -> 51447.028 | J12: 267.07692 | K12: =J12*D12 -> 51447.028 | L12: 9 | M12: =L12*D12 -> 1733.67 | N12: =L12/J12 -> 0.033698157 | O12: 267.07692 | P12: =O12*D12 -> 51447.028 | S12: 267.07692 | T12: =S12*D12 -> 51447.028 | W12: =ZEESHAN!W12+SAQIB!W12 -> 992 | X12: =W12*D12 -> 191088.96 | Y12: 19 | Z12: =Y12/W12 -> 0.019153226
A13: 6 | B13: SUDROPROXIM TAB | C13: 100's | D13: 195 | E13: 30 | F13: =W13/26*7 -> 42 | G13: =F13*D13 -> 8190 | J13: 42 | K13: =J13*D13 -> 8190 | L13: 0 | M13: =L13*D13 -> 0 | N13: =L13/J13 -> 0 | O13: 42 | P13: =O13*D13 -> 8190 | S13: 42 | T13: =S13*D13 -> 8190 | W13: =ZEESHAN!W13+SAQIB!W13 -> 156 | X13: =W13*D13 -> 30420 | Y13: 0 | Z13: =Y13/W13 -> 0
A14: 7 | B14: SUDROPROXIM FORTE TAB | C14: 100's | D14: 648.52 | E14: 30 | F14: =W14/26*7 -> 42 | G14: =F14*D14 -> 27237.84 | J14: 42 | K14: =J14*D14 -> 27237.84 | L14: 10 | M14: =L14*D14 -> 6485.2 | N14: =L14/J14 -> 0.23809524 | O14: 42 | P14: =O14*D14 -> 27237.84 | S14: 42 | T14: =S14*D14 -> 27237.84 | W14: =ZEESHAN!W14+SAQIB!W14 -> 156 | X14: =W14*D14 -> 101169.12 | Y14: 0 | Z14: =Y14/W14 -> 0
A15: 8 | B15: TECHFEN P Tab 50mg | C15: 20's | D15: 51 | E15: 300 | F15: =W15/26*7 -> 417.30769 | G15: =F15*D15 -> 21282.692 | J15: 417.30769 | K15: =J15*D15 -> 21282.692 | L15: 35 | M15: =L15*D15 -> 1785 | N15: =L15/J15 -> 0.083870968 | O15: 417.30769 | P15: =O15*D15 -> 21282.692 | S15: 417.30769 | T15: =S15*D15 -> 21282.692 | W15: =ZEESHAN!W15+SAQIB!W15 -> 1550 | X15: =W15*D15 -> 79050 | Y15: 195 | Z15: =Y15/W15 -> 0.12580645
A16: 9 | B16: Zicure 250mg Cap 10's | C16: 10's | D16: 189.25 | E16: 560 | F16: =W16/26*7 -> 779.15385 | G16: =F16*D16 -> 147454.87 | J16: 779.15385 | K16: =J16*D16 -> 147454.87 | L16: 11 | M16: =L16*D16 -> 2081.75 | N16: =L16/J16 -> 0.014117879 | O16: 779.15385 | P16: =O16*D16 -> 147454.87 | S16: 779.15385 | T16: =S16*D16 -> 147454.87 | W16: =ZEESHAN!W16+SAQIB!W16 -> 2894 | X16: =W16*D16 -> 547689.5 | Y16: 191 | Z16: =Y16/W16 -> 0.065998618
A17: 10 | B17: Zicure 250mg Cap 6's | C17: 6's | D17: 128.86 | E17: 550 | F17: =W17/26*7 -> 765.15385 | G17: =F17*D17 -> 98597.725 | J17: 765.15385 | K17: =J17*D17 -> 98597.725 | L17: 0 | M17: =L17*D17 -> 0 | N17: =L17/J17 -> 0 | O17: 765.15385 | P17: =O17*D17 -> 98597.725 | S17: 765.15385 | T17: =S17*D17 -> 98597.725 | W17: =ZEESHAN!W17+SAQIB!W17 -> 2842 | X17: =W17*D17 -> 366220.12 | Y17: 2 | Z17: =Y17/W17 -> 0.00070372977
A18: 11 | B18: Curatral 100mg Cap | C18: 4's | D18: 94.9 | E18: 650 | F18: =W18/26*7 -> 904.07692 | G18: =F18*D18 -> 85796.9 | J18: 904.07692 | K18: =J18*D18 -> 85796.9 | L18: 59 | M18: =L18*D18 -> 5599.1 | N18: =L18/J18 -> 0.065259934 | O18: 904.07692 | P18: =O18*D18 -> 85796.9 | S18: 904.07692 | T18: =S18*D18 -> 85796.9 | W18: =ZEESHAN!W18+SAQIB!W18 -> 3358 | X18: =W18*D18 -> 318674.2 | Y18: 393 | Z18: =Y18/W18 -> 0.11703395
A19: 12 | B19: TECHFEN SR Tab 100mg | C19: 30's | D19: 85.33 | E19: 550 | F19: =W19/26*7 -> 765.15385 | G19: =F19*D19 -> 65290.578 | J19: 765.15385 | K19: =J19*D19 -> 65290.578 | L19: 563 | M19: =L19*D19 -> 48040.79 | N19: =L19/J19 -> 0.73579974 | O19: 765.15385 | P19: =O19*D19 -> 65290.578 | S19: 765.15385 | T19: =S19*D19 -> 65290.578 | W19: =ZEESHAN!W19+SAQIB!W19 -> 2842 | X19: =W19*D19 -> 242507.86 | Y19: 957 | Z19: =Y19/W19 -> 0.33673469
... A22: 15 | B22: Pirotech 20mg Tab | C22: 20's | D22: 89.64 | E22: 300 | F22: =W22/26*7 -> 417.30769 | G22: =F22*D22 -> 37407.462 | J22: 417.30769 | K22: =J22*D22 -> 37407.462 | L22: 113 | M22: =L22*D22 -> 10129.32 | N22: =L22/J22 -> 0.27078341 | O22: 417.30769 | P22: =O22*D22 -> 37407.462 | S22: 417.30769 | T22: =S22*D22 -> 37407.462 | W22: =ZEESHAN!W22+SAQIB!W22 -> 1550 | X22: =W22*D22 -> 138942 | Y22: 179 | Z22: =Y22/W22 -> 0.11548387
